Workbook

Sheet CODIFICACIÓN_DPA
A1: DPA_DESCRI | B1: COD_DPA | D1: MODALIDAD_DESCRIP | E1: COD_MODALIDAD | G1: NODO_DESCRP | H1: NODO_LOCALIDAD | J1: CENTRALIDAD_DESCRIP | K1: COD_CENTRALIDAD
A2: BELISARIO QUEVEDO | B2: 170101 | D2: NATURAL | E2: NA | G2: URBANO | H2: 01 | J2: Centro Histórico | K2: 01
A3: CARCELÉN | B3: 170102 | D3: GASTRONÓMICO | E3: GA | G3: RURAL | H3: 02 | J3: La Mariscal | K3: 02
A4: CENTRO HISTÓRICO | B4: 170103 | D4: CULTURAL | E4: CU | J4: Centro Norte | K4: 03
A5: COCHAPAMBA | B5: 170104 | D5: AVENTURA | E5: AV | J5: Parroquias Equinocciales | K5: 04
A6: COMITÉ DEL PUEBLO | B6: 170105 | D6: COMUNITARIO | E6: CO | J6: Chocó Andino | K6: 05
A7: COTOCOLLAO | B7: 170106 | J7: Ruta Escondida | K7: 06
A8: CHILIBULO | B8: 170107 | J8: Valle de los Chillos | K8: 07
A9: CHILLOGALLO | B9: 170108 | J9: Valle de Tumbaco | K9: 08
A10: CHIMBACALLE | B10: 170109 | J10: Calderón | K10: 09
A11: EL CONDADO | B11: 170110
A12: GUAMANÍ | B12: 170111
A13: IÑAQUITO | B13: 170112
A14: ITCHIMBIA | B14: 170113
A15: JIPIJAPA | B15: 170114 | C15: URBANAS
A16: KENNEDY | B16: 170115
A17: LA ARGELIA | B17: 170116
A18: LA CONCEPCIÓN | B18: 170117
A19: LA ECUATORIANA | B19: 170118
A20: LA FERROVIARIA | B20: 170119
A21: LA LIBERTAD | B21: 170120 | D21: CÓDIGO QT
A22: LA MAGDALENA | B22: 170121 | D22: 170112GA0103001
A23: LA MENA | B23: 170122
A24: MARISCAL SUCRE | B24: 170123
A25: PONCEANO | B25: 170124 | D25: PARROQUIA | E25: MODALIDAD | F25: NODO | G25: CENTRALIDAD | H25: ORDEN EN LISTADO
A26: PUENGASÍ | B26: 170125 | D26: 170112 | E26: GA | F26: 01 | G26: 03 | H26: 001
A27: QUITUMBE | B27: 170126 | D27: IÑAQUITO | E27: GASTRONÓMICO | F27: URBANO | G27: Centro Norte | H27: 001
A28: RUMIPAMBA | B28: 170127
A29: SAN BARTOLO | B29: 170128
A30: SAN ISIDRO DEL INCA | B30: 170129
A31: SAN JUAN | B31: 170130
A32: SOLANDA | B32: 170131
A33: TURUBAMBA | B33: 170132
A34: ALANGASÍ | B34: 170151
A35: AMAGUAÑA | B35: 170152
A36: ATAHUALPA | B36: 170153
A37: CALACALÍ | B37: 170154
A38: CALDERÓN | B38: 170155
A39: CONOCOTO | B39: 170156
... A43: EL QUINCHE | B43: 170160
...

Sheet ESTRUCTURA CÓDIGO
A1: FICHA PARA EL LEVANTAMIENTO DE EXPERIENCIAS TURÍSTICAS
A3: CÓDIGO DE LA EXPERIENCIA
A5: El código, está compuesto por 15 dígitos (caracteres alfanuméricos), únicos e irrepetibles, mismo que aparecerá al inicio de la ficha para su identificación.
A6: 1. División Política Administrativa (DPA) obtenida del Clasificador Geográfico 2023 del Instituto Nacional de Estadística y Censos - INEC, (códigos provincial, cantonal y parroquial).
A7: 2. Se colocará las letras iniciales de la modalidad de la experiencia ejemplo: Gastronómica "GA"
A8: 3. Clasificación de experiencia turística (Nodo), (ver documento Centralidades - Nodos Turísticos Complementarios Urbanos y Rurales, 2024).
A9: 4. Clasificación de experiencia turística (Centralidad), (ver documento Centralidades - Nodos Turísticos Complementarios Urbanos y Rurales, 2024).
A10: 5. FInalmente; los tres dígitos finales corresponden al orden en que se levante la información de las experiencias turísticas que iniciará desde 001.
A14: FUENTE: Manual Metodología para Jerarquización de Atractivos y Generación de Espacios Turísticos, MINTUR 2017.
A15: Centralidades - Nodos Turísticos Complementarios Urbanos y Rurales, QUITO TURISMO 2024.

Sheet EXPERIENCIAS
A1: N° | B1: ESTADO EXPERIENCIA | C1: CÓDIGO EXPERIENCIA QT | D1: PARROQUIA | E1: NODO | F1: CENTRALIDAD | G1: MODALIDAD | H1: NOMBRE DE LA EXPERIENCIA | I1: BREVE DESCRIPCIÓN Y ACTIVIDADES A REALIZAR | J1: DIRECCIÓN | K1: LATITUD | L1: LONGITUD | M1: TIEMPO DE DURACIÓN | N1: HORARIO DE ATENCIÓN | O1: COSTO | P1: CAPACIDAD | Q1: RESTRICCIONES | R1: CONTACTOS
A2: 001 | B2: ACTIVO | C2: =CONCATENATE(VLOOKUP($D2,CODIFICACIÓN_DPA!$A$2:$B$66,2,FALSE),VLOOKUP($G2,CODIFICACIÓN_DPA!$D$2:$E$6,2,FALSE),CONCATENATE(VLOOKUP($E2,CODIFICACIÓN_DPA!$G$2:$H$3,2,FALSE),VLOOKUP($F2,CODIFICACIÓN_DPA!$J$2:$K$10,2,FALSE)),A2) -> 170154CO0205001 | D2: CALACALÍ | E2: RURAL | F2: Chocó Andino | G2: COMUNITARIO | H2: Comunidad Yunguilla | I2: Sumérgete en el Chocó Andino y explorar su rica herencia cultural y natural, al tiempo que apoyas activamente a la comunidad local. La comunidad Yunguilla ofrece a los visitantes una experiencia auténtica de la ruralidad, disfrutando de emocionantes recorridos guiados por antiguos caminos precolombinos, aventúrate en apasionantes trekkings por reservas naturales cercanas y conecta con la naturaleza a través de experiencias de camping bajo el cielo estrellado. ¡Descubre la autenticidad de su gente mientras contribuyes al desarrollo sostenible de la región! | J2: Parroquia Calacalí, km 12 vía al noroccidente de Quito, en el ACUS Yunguilla del Distrito Metropolitano de Quito. | K2: -0.020786319 | L2: -78.553248 | M2: 3 a 4 horas | N2: 24 horas Todos los días Previa reserva | O2: Depende mucho del servicio que se solicite | P2: - Alojamiento comunitario capaciadad 30 pax - Restaurante capacidad 80 pax - Salón de eventos capacida 80 personas - Senderos establecidos: 4 - Miradores: 2 - Tours organizados: 6 alternativas - Guías nativos - Tiendas de artesanías y productos orgánicos | Q2: Prohibido el ingreso de mascotas debido a su estatus como Área de Conservación y Uso Sustentable (ACUS) y su modelo de turismo comunitario, que busca proteger la fauna silvestre (como el oso de anteojos y diversas aves endémicas) de posibles enfermedades o estrés causado por animales domésticos. | R2: (593) 98 021 5476 https://www.yunguilla.org.ec/contact-us/ info@yunguilla.org.ec (593) 99 954 1537
A3: 002 | B3: ACTIVO | C3: =CONCATENATE(VLOOKUP($D3,CODIFICACIÓN_DPA!$A$2:$B$66,2,FALSE),VLOOKUP($G3,CODIFICACIÓN_DPA!$D$2:$E$6,2,FALSE),CONCATENATE(VLOOKUP($E3,CODIFICACIÓN_DPA!$G$2:$H$3,2,FALSE),VLOOKUP($F3,CODIFICACIÓN_DPA!$J$2:$K$10,2,FALSE)),A3) -> 170155CO0204002 | D3: CALDERÓN | E3: RURAL | F3: Parroquias Equinocciales | G3: COMUNITARIO | H3: Chucchurillos Ñaupa Ayllu Manta | I3: Chucchurillos Ñaupa Ayllu Manta celebra la herencia Kitu Kara con danzas, rituales y relatos que honran a la Pachamama, en torno al tzáwar (agave andino), “planta de las mil maravillas”. La experiencia integra saberes intergeneracionales, festividades de siembra y cosecha del tzawarmishki, gastronomía ancestral, mieles y bebidas tradicionales, además de artesanías en cabuya que revelan usos sostenibles del territorio. Un encuentro cultural auténtico, inmersivo y emotivo, donde la memoria viva de los Andes se manifiesta en cada canto, aroma y textura. | J3: Quito-Pomasqui Barrio el Común | K3: -0.057963558 | L3: -78.449687 | N3: Bajo reserva | O3: Depende del grupo y actividad | P3: Se adapta a la necesidad del grupo. | R3: (02) 235 8001 (+593) 98 765 6946 Email: chucchurillos@hotmail.com Whatsapp: (+593) 97 905 4213
A4: 003 | B4: ACTIVO | C4: =CONCATENATE(VLOOKUP($D4,CODIFICACIÓN_DPA!$A$2:$B$66,2,FALSE),VLOOKUP($G4,CODIFICACIÓN_DPA!$D$2:$E$6,2,FALSE),CONCATENATE(VLOOKUP($E4,CODIFICACIÓN_DPA!$G$2:$H$3,2,FALSE),VLOOKUP($F4,CODIFICACIÓN_DPA!$J$2:$K$10,2,FALSE)),A4) -> 170155CO0209003 | D4: CALDERÓN | E4: RURAL | F4: Calderón | G4: COMUNITARIO | H4: Ecoferia Allpa Maki | I4: Ecoferia Allpa Maki es la vitrina agroecológica de la Comuna Llano Grande: una asociación de huertos que impulsa el estilo de vida LOHAS (Vida Saludable y Sustentable) y la economía solidaria Kitu Kara, fusionando saberes ancestrales, soberanía alimentaria y empoderamiento comunitario. Entre agro-biodiversidad, productos frescos “de la mata a la olla”, cocina en vivo y manifestaciones culturales, la feria celebra el respeto a la Pachamama, la justicia alimentaria y la producción responsable, ofreciendo un mercado vivo donde salud, sabor y comunidad se encuentran en armonía con el planeta. | J4: Llano Grande, Quito | K4: -0.12329098 | L4: -78.426923 | M4: 1 hora | N4: Domingos de 07h00 a 12h00 Puede variar el horario | O4: Costo de los productos que se vayan a comprar | P4: Se adapta a la necesidad del grupo. | R4: allpamaki2021@gmail.com
A5: 004 | B5: ACTIVO | C5: =CONCATENATE(VLOOKUP($D5,CODIFICACIÓN_DPA!$A$2:$B$66,2,FALSE),VLOOKUP($G5,CODIFICACIÓN_DPA!$D$2:$E$6,2,FALSE),CONCATENATE(VLOOKUP($E5,CODIFICACIÓN_DPA!$G$2:$H$3,2,FALSE),VLOOKUP($F5,CODIFICACIÓN_DPA!$J$2:$K$10,2,FALSE)),A5) -> 170101CU0102004 | D5: BELISARIO QUEVEDO | E5: URBANO | F5: La Mariscal | G5: CULTURAL | H5: Mercado Santa Clara | I5: Un ícono donde confluyen tradiciones ancestrales y vorágine urbana actual, el mercado Santa Clara seduce los sentidos. En sus pasillos, las caceras ofrecen especias, frutas, verduras y flores, mientras en el patio de comidas desborda gastronomía tradicional como hornado, yaguarlocro y seco de chivo con refrescantes jugos y batidos de huertos andinos. Afuera, artesanos exhiben trenzadas creaciones de mimbre, cabuya y alfarería. Las "yuyeras", mujeres que realizan "limpias", ritual curativo ancestral de purificación y florecimiento con flores y plantas andinas. Una cautivadora experiencia sensorial. | J5: Calle Antonio de Ulloa | K5: -0.19958008 | L5: -78.49946 | M5: 1 hora | N5: Lunes a Sábado 07h00 a 17h30 domingo 07h00 a 15h00 | O5: Depende del grupo y actividad | P5: Máximo 20 pax | Q5: Se consulta al momento de la limpia, si desea que se le limpie con el licor | R5: (+593) 99 271 8696 (+593) 98 742 0863
A6: 005 | B6: ACTIVO | C6: =CONCATENATE(VLOOKUP($D6,CODIFICACIÓN_DPA!$A$2:$B$66,2,FALSE),VLOOKUP($G6,CODIFICACIÓN_DPA!$D$2:$E$6,2,FALSE),CONCATENATE(VLOOKUP($E6,CODIFICACIÓN_DPA!$G$2:$H$3,2,FALSE),VLOOKUP($F6,CODIFICACIÓN_DPA!$J$2:$K$10,2,FALSE)),A6) -> 170112CU0103005 | D6: IÑAQUITO | E6: URBANO | F6: Centro Norte | G6: CULTURAL | H6: Salsoteca Lavoe | I6: Salsoteca Lavoe es el punto de encuentro ideal para los amantes de la salsa y para quienes desean descubrir la magia de este apasionante ritmo latino. Su ambiente vibrante acoge tanto a locales como a visitantes extranjeros que buscan vivir la noche quiteña al compás de la música y el baile. El lugar ofrece talleres de salsa y bachata para todos los niveles, invitando a disfrutar, aprender y dejarse llevar por la energía contagiosa del movimiento. Cada noche, la música en vivo y los DJ invitados transforman el espacio en una auténtica fiesta caribeña, donde la alegría, el sabor y la danza garantizan una experiencia inolvidable. | J6: "Iñaquito E2-17 y NNUU (Junto a la gasolinera Primax)" | K6: -0.1744392 | L6: -78.487209 | M6: Talleres de baile se realiza 20h00 durante una hora, en el horario de atención | N6: Miércoles a Sábado: 19h00 a 03h00 Domingos: 15h00 a 00h00 | O6: $7.00 - $8.00 | Q6: Mayores de 18 años | R6: Julio Olmedo (+593) 96 400 4478 lavoe.quito@gmail.com
A7: 006 | B7: ACTIVO | C7: =CONCATENATE(VLOOKUP($D7,CODIFICACIÓN_DPA!$A$2:$B$66,2,FALSE),VLOOKUP($G7,CODIFICACIÓN_DPA!$D$2:$E$6,2,FALSE),CONCATENATE(VLOOKUP($E7,CODIFICACIÓN_DPA!$G$2:$H$3,2,FALSE),VLOOKUP($F7,CODIFICACIÓN_DPA!$J$2:$K$10,2,FALSE)),A7) -> 170103CU0101006 | D7: CENTRO HISTÓRICO | E7: URBANO | F7: Centro Histórico | G7: CULTURAL | H7: Quito Eterno | I7: Quito Eterno convierte el Centro Histórico en un gran escenario donde la ciudad se cuenta a sí misma: recorridos teatralizados que enlazan iglesias, conventos, museos y barrios emblemáticos con una dramaturgia cuidada, protagonizada por personajes tradicionales que revelan leyendas, oficios antiguos y costumbres arraigadas. La arquitectura colonial y republicana dialoga con el patrimonio intangible en un hilo narrativo que emociona, mientras la música, la luz y la palabra ejecutada en vivo dibujan atmósferas íntimas en plazas, claustros y callejones. Es una experiencia estética y cultural de alta calidad, que rescata memoria y sentido de lugar, y hace brillar la riqueza histórica de Quito con sensibilidad contemporánea. | J7: Loma Grande. Fernández Madrid N 113 y Rocafuerte Capilla de los Milagros | K7: -0.22662326 | L7: -78.509493 | M7: 1 hora y 30 minutos | N7: Sábado 11h00 16h00,16h30 puede variar hasta las 19h00 Miércoles 19h00 | O7: Miércoles $20.00 (2x1) Sábados 11h00 ( $10.00 adultos) ($6.00 Tarifa diferenciada) Sábados 16h00 a 19h00 ($20.00 adultos) ($10.00 tarifa diferenciada) Pronto pago ($17.00 adultos) ($7.00 Tarifa diferenciada) | Q7: Recorridos a pie, Si se requiere un guía que hable en otro idioma, comunicar con anticipación al contacto 098 488 1018. Se puede reservar hasta con 4 horas de anticipación | R7: http://quitoeterno.org/ (+593) 98 488 1018 info@quitoeterno.org Adrián Gutiérrez
A8: 007 | B8: ACTIVO | C8: =CONCATENATE(VLOOKUP($D8,CODIFICACIÓN_DPA!$A$2:$B$66,2,FALSE),VLOOKUP($G8,CODIFICACIÓN_DPA!$D$2:$E$6,2,FALSE),CONCATENATE(VLOOKUP($E8,CODIFICACIÓN_DPA!$G$2:$H$3,2,FALSE),VLOOKUP($F8,CODIFICACIÓN_DPA!$J$2:$K$10,2,FALSE)),A8) -> 170123CU0102007 | D8: MARISCAL SUCRE | E8: URBANO | F8: La Mariscal | G8: CULTURAL | H8: Mon Atelier Quito | I8: En Mon Atelier, tanto parejas como padres e hijos disfrutan de una experiencia creativa y divertida mientras aprenden técnicas de pintura bajo la guía de talleristas especializados. Además de sumergirse en el arte, tienen la oportunidad de degustar exquisitos quesos y vinos seleccionados cuidadosamente para estimular su creatividad. Durante aproximadamente 2 horas, los artistas los acompañan paso a paso, asegurando que al finalizar, cada participante haya creado una obra maestra única. Todo esto se desarrolla en un ambiente creativo y estimulante, ideal para compartir momentos inolvidables en compañía de seres queridos. | J8: José Tamayo N24-525 y Luis Cordero | K8: -0.20341724 | L8: -78.485623 | M8: 2 horas | N8: Depende de las actividades que promocionen. Sin embargo su horario para actividad libre es: Lunes a Sabado en la mañana de 10:00-12:00 y en la tarde de 4:00 a 6:00 | O8: Costo por persona: $35.00 Incluye todos los materiales y una copa de vino | P8: Se adapta a la necesidad | R8: https://www.monatelierecuador.com/ 099 643 7788
A9: 008 | B9: ACTIVO | C9: =CONCATENATE(VLOOKUP($D9,CODIFICACIÓN_DPA!$A$2:$B$66,2,FALSE),VLOOKUP($G9,CODIFICACIÓN_DPA!$D$2:$E$6,2,FALSE),CONCATENATE(VLOOKUP($E9,CODIFICACIÓN_DPA!$G$2:$H$3,2,FALSE),VLOOKUP($F9,CODIFICACIÓN_DPA!$J$2:$K$10,2,FALSE)),A9) -> 170130CU0101008 | D9: SAN JUAN | E9: URBANO | F9: Centro Histórico | G9: CULTURAL | H9: La Caponata | I9: La Caponata es un rincón encantador del Centro Histórico que conquista con el auténtico sabor de la cocina italiana y siciliana. En un ambiente colonial acogedor, con patio interior y detalles artísticos, se disfrutan pastas frescas, pizzas al estilo tradicional y opciones vegetarianas y veganas que sorprenden por su sabor. A esto se suma la magia de la música en vivo, que crea una atmósfera vibrante y especial, haciendo de cada velada un encuentro inolvidable. Además, la experiencia se enriquece con actividades culturales como el tour a pie “Pata Caliente” a través de talleres y tiendas especializadas. | J9: García Moreno y Manabí Centro Histórico | K9: -0.21755945 | L9: -78.510565 | M9: 1 hora 30 minutos | N9: - Lunes a Sábado: 12h00 a 00h00 - Domingo: 12h00 a 20h00 | O9: Rango de precios $ 6.00 - $14.00 | Q9: Mayores de 18 años Recorridos a pie | R9: Pablo Iturralde (+593) 98 014 8251 info@lacaponata.com
A10: 009 | B10: ACTIVO | C10: =CONCATENATE(VLOOKUP($D10,CODIFICACIÓN_DPA!$A$2:$B$66,2,FALSE),VLOOKUP($G10,CODIFICACIÓN_DPA!$D$2:$E$6,2,FALSE),CONCATENATE(VLOOKUP($E10,CODIFICACIÓN_DPA!$G$2:$H$3,2,FALSE),VLOOKUP($F10,CODIFICACIÓN_DPA!$J$2:$K$10,2,FALSE)),A10) -> 170103CU0101009 | D10: CENTRO HISTÓRICO | E10: URBANO | F10: Centro Histórico | G10: CULTURAL | H10: Escuela Quiteña: Taller de Taracea | I10: La Escuela Quiteña: Taller de Taracea deslumbra con el arte de las incrustaciones finas—madera, concha, hueso, nácar y metales—que dan vida a piezas de autor, con los emblemáticos bargueños como sello distintivo. En este atelier, la maestría del tallado y el taraceado dialoga con la pintura y la escultura, integrando legado quiteño y diseño contemporáneo en obras de acabado exquisito. Un espacio donde el oficio alcanza categoría de arte, la historia se hace tangible en cada detalle y la elegancia artesanal conquista a primera vista. | J10: Calle Morales y Calle Venezuela , Casa 9-89 calle la “Ronda “ centro histórico de Quito , Quito, Ecuador | K10: -0.224263 | L10: -78.514054 | M10: 2 horas diarias | N10: Lunes a Viernes 9h00 a 18h00 | O10: $ 20 dólares por persona por hora | P10: mínimo 2 pax, máximo 15 pax | Q10: (No incluye materiales) | R10: José Luis Jiménez (+593) 98 444 1999 jjimenezarteaga@gmail.com
A11: 010 | B11: ACTIVO | C11: =CONCATENATE(VLOOKUP($D11,CODIFICACIÓN_DPA!$A$2:$B$66,2,FALSE),VLOOKUP($G11,CODIFICACIÓN_DPA!$D$2:$E$6,2,FALSE),CONCATENATE(VLOOKUP($E11,CODIFICACIÓN_DPA!$G$2:$H$3,2,FALSE),VLOOKUP($F11,CODIFICACIÓN_DPA!$J$2:$K$10,2,FALSE)),A11) -> 170103CU0101010 | D11: CENTRO HISTÓRICO | E11: URBANO | F11: Centro Histórico | G11: CULTURAL | H11: Hojalatería Silva | I11: En el corazón de Quito, la Hojalatería Silva mantiene viva una de las tradiciones más emblemáticas del arte popular quiteño. Bajo la dedicación de Martha Silva, quien heredó este oficio de su padre, el taller invita a los visitantes a descubrir el fascinante mundo de la hojalata a través de talleres participativos donde se aprende, se crea y se valora el trabajo artesanal. Cada pieza, desde coloridos juguetes hasta delicados utensilios, refleja la historia, la destreza y la pasión de generaciones de artesanos. Al finalizar la experiencia, los visitantes pueden adquirir piezas únicas y llevar consigo un auténtico recuerdo del arte tradicional quiteño. | J11: Calle Morales - La Ronda casa 925 | K11: -0.224263 | L11: -78.514054 | M11: 45 minutos | N11: lunes a jueves 10h00 a 17h00 viernes y sábados 10h00 - 20h00 domingo 10h00 - 16h00 | O11: Elaboración de silbato: $3.00 Elaboración de repujado: $3.00 Taller de blindado: $5.00 | P11: máximos 15 pax | R11: Marthita Silva (+593) 98 424 7622
A12: 011 | B12: ACTIVO | C12: =CONCATENATE(VLOOKUP($D12,CODIFICACIÓN_DPA!$A$2:$B$66,2,FALSE),VLOOKUP($G12,CODIFICACIÓN_DPA!$D$2:$E$6,2,FALSE),CONCATENATE(VLOOKUP($E12,CODIFICACIÓN_DPA!$G$2:$H$3,2,FALSE),VLOOKUP($F12,CODIFICACIÓN_DPA!$J$2:$K$10,2,FALSE)),A12) -> 170103CU0101011 | D12: CENTRO HISTÓRICO | E12: URBANO | F12: Centro Histórico | G12: CULTURAL | H12: Mercado De San Francisco | I12: Ubicado en el corazón del Centro Histórico, el Mercado de San Francisco es uno de los más antiguos y auténticos de Quito. Este espacio patrimonial conserva la esencia de la vida quiteña, donde los aromas, los colores y las tradiciones se entrelazan para ofrecer una experiencia única. Reconocido por ser el epicentro de las “curas” o “limpias” realizadas por las tradicionales hierbateras, el mercado invita a descubrir la sabiduría ancestral de la medicina andina, un legado que ha perdurado por generaciones. Además, sus puestos gastronómicos ofrecen una deliciosa muestra de la cocina popular quiteña, con caldos, jugos y platos típicos preparados con el sabor de la tradición. Visitar el Mercado de San Francisco es sumergirse en el corazón cultural de Quito, donde cada rincón cuenta una historia y cada aroma despierta la memoria de lo auténtico. | J12: Calle Rocafuerte. | K12: -0.21973704 | L12: -78.518576 | M12: 1 hora | N12: lunes a domingo 07h00 - 16h10 | O12: Depende del grupo y actividad | Q12: Se consulta al momento de la limpia, si desea que se le limpie con el licor
A13: 012 | B13: ACTIVO | C13: =CONCATENATE(VLOOKUP($D13,CODIFICACIÓN_DPA!$A$2:$B$66,2,FALSE),VLOOKUP($G13,CODIFICACIÓN_DPA!$D$2:$E$6,2,FALSE),CONCATENATE(VLOOKUP($E13,CODIFICACIÓN_DPA!$G$2:$H$3,2,FALSE),VLOOKUP($F13,CODIFICACIÓN_DPA!$J$2:$K$10,2,FALSE)),A13) -> 170112GA0103012 | D13: IÑAQUITO | E13: URBANO | F13: Centro Norte | G13: GASTRONÓMICO | H13: TO'AK Chocolate | I13: TO'AK ofrece una "Experiencia de Chocolate y Arte" donde los participantes disfrutarán de un recorrido privado por la casa del maestro Oswaldo Guayasamín, explorando todas sus estancias más íntimas de uno de los artistas más creativos de América Latina en el siglo pasado. La experiencia sensorial continúa con una degustación completa de granos de cacao crudos y tostados, así como de cuatro ediciones diferentes de To'ak Chocolate. Durante esta experiencia, los participantes recibirán explicaciones sobre las diferentes variedades de cacao ecuatoriano, su lugar de origen, los métodos de fermentación y el envejecimiento en barricas. Se explorará cómo estas variables de producción influyen en el perfil de sabor y aroma de cada expresión del chocolate. | J13: Mariano Calvache E18-94 y, Quito 170135 | K13: -0.19024789 | L13: -78.469012 | M13: 2 horas | N13: Lunes a Viernes 09h00 a 18h00 (EST) | O13: $125.00 por persona, con un mínimo de dos personas y un máximo de ocho personas. Los niños hasta 12 años entran gratis si van acompañados de dos adultos. | P13: 2 personas mínimo, 8 máximo | R13: Llamada/Texto: +1 (805) 600 8625 Ecuador: (+593) 2322 7520 https://toakchocolate.com/pages/chocolate-tour
A14: 013 | B14: ACTIVO | C14: =CONCATENATE(VLOOKUP($D14,CODIFICACIÓN_DPA!$A$2:$B$66,2,FALSE),VLOOKUP($G14,CODIFICACIÓN_DPA!$D$2:$E$6,2,FALSE),CONCATENATE(VLOOKUP($E14,CODIFICACIÓN_DPA!$G$2:$H$3,2,FALSE),VLOOKUP($F14,CODIFICACIÓN_DPA!$J$2:$K$10,2,FALSE)),A14) -> 170103GA0101013 | D14: CENTRO HISTÓRICO | E14: URBANO | F14: Centro Histórico | G14: GASTRONÓMICO | H14: Chez Tiff | I14: En el corazón de la ciudad, Chez Tiff invita a vivir una experiencia sensorial que celebra el cacao ecuatoriano en su máxima expresión. Esta chocolatería artesanal, pionera en el proceso “bean to bar”, transforma granos seleccionados de distintas regiones del país en auténticas obras de arte comestibles. Los visitantes pueden disfrutar de catas guiadas, conocer el proceso de elaboración del chocolate y descubrir la historia y diversidad del cacao nacional, reconocido entre los mejores del mundo. Cada barra, bombón o trufa elaborada en Chez Tiff refleja la pasión por la calidad, la innovación y el compromiso con la producción sostenible. | J14: García Moreno N7-39 y, Quito 170401 | K14: -0.21769412 | L14: -78.510837 | M14: Capacitación 1: 30 minutos Capacitación 2: 40 minutos Capacitación 3: 90 minutos Capacitación 4: 90 minutos Capacitación 5: 60 minutos | N14: Lunes a Viernes de 10h00 a 18h30 Sabado y Domingo de 11h00 a 17h30 | O14: Capacitación 1: De 1 pax a 5 pax: $20,00 + IVA (costo por grupo) A partir de la 6ta persona: $3,50 + IVA (costo por persona) Capacitación 2: 1 a 5 $39,50 + IVA (costo por grupo) De 6 pax en adelante: $6,50 + IVA (costo por persona) Capacitación 3: De 1 pax a 5 pax: $54 + IVA (costo por grupo) De 6 pax en adelante: $ 10,50 + IVA (costo por persona) Capacitación 4: COSTOS: 1 a 5 pax: $85 + IVA (costo por grupo) 6 a 9 pax: $15 + IVA (costo por persona) Capacitación 5: 1 a 5 pax: $85 + IVA (costo por grupo) 6 a 9 pax: $15 + IVA (costo por persona) | P14: 30 personas maxino | R14: Cristina Báez-Montenegro WhatsApp: (+593) 99 625 8948.
A15: 014 | B15: ACTIVO | C15: =CONCATENATE(VLOOKUP($D15,CODIFICACIÓN_DPA!$A$2:$B$66,2,FALSE),VLOOKUP($G15,CODIFICACIÓN_DPA!$D$2:$E$6,2,FALSE),CONCATENATE(VLOOKUP($E15,CODIFICACIÓN_DPA!$G$2:$H$3,2,FALSE),VLOOKUP($F15,CODIFICACIÓN_DPA!$J$2:$K$10,2,FALSE)),A15) -> 170123GA0102014 | D15: MARISCAL SUCRE | E15: URBANO | F15: La Mariscal | G15: GASTRONÓMICO | H15: Chocolate Pacari | I15: Chocolate Pacari ofrece experiencias de cata de chocolate y elaboración de trufas, durante las cuales los participantes pueden degustar una selección de bombones mientras se sumergen en la rica historia del cacao en Ecuador. Además, tienen la oportunidad de conocer la dedicada trayectoria y compromiso de sostenibilidad de Pacari con los productores de cacao. Estas catas representan una experiencia sensorial completa, invitando a los participantes a agudizar sus sentidos para apreciar las cualidades únicas de cada chocolate. Se explora su aspecto visual, aroma, sonido al partirlo y, por supuesto, su delicioso sabor. Esta experiencia no solo es placentera, sino también educativa, brindando la oportunidad de aprender sobre el proceso histórico del cacao ecuatoriano. | J15: Julio Zaldumbide N24-713 Y, Quito 170150 | K15: -0.20590726 | L15: -78.480807 | M15: 1 hora | N15: Lunes a Jueves 8h00 a 20h00 Viernes a Sábado a domingo 8h00 a 10h00 | O15: $10.00 por persona, el guía y personal gratis. | P15: 1 persona - 50 personas | Q15: Alérgicos a las almendras | R15: "https://www.facebook.com/PaccariChocolate (02) 380 9230/ 0958749233 Alejandra Calderón."
A16: 015 | B16: ACTIVO | C16: =CONCATENATE(VLOOKUP($D16,CODIFICACIÓN_DPA!$A$2:$B$66,2,FALSE),VLOOKUP($G16,CODIFICACIÓN_DPA!$D$2:$E$6,2,FALSE),CONCATENATE(VLOOKUP($E16,CODIFICACIÓN_DPA!$G$2:$H$3,2,FALSE),VLOOKUP($F16,CODIFICACIÓN_DPA!$J$2:$K$10,2,FALSE)),A16) -> 170103GA0101015 | D16: CENTRO HISTÓRICO | E16: URBANO | F16: Centro Histórico | G16: GASTRONÓMICO | H16: Hotel Carlota | I16: Ubicado en una casa patrimonial del siglo XIX, el Hotel Carlota combina historia, diseño y sostenibilidad en pleno corazón del Centro Histórico de Quito. Su restauración ha preservado los detalles arquitectónicos originales, integrándolos con un estilo moderno que resalta la autenticidad de su entorno. Cada habitación cuenta una historia distinta, inspirada en la ciudad y su cultura, mientras que los espacios comunes invitan al descanso y la contemplación. Su terraza ofrece una vista privilegiada de los tejados coloniales y las cúpulas quiteñas, creando un ambiente ideal para disfrutar de una bebida o una cena con encanto local. El Hotel Carlota es más que un alojamiento: es una experiencia urbana y patrimonial que refleja la esencia de Quito con elegancia, calidez y compromiso ambiental. | J16: Benalcázar N 6-26 y Mejía. Quito, Ecuador | K16: -0.21801886 | L16: -78.512052 | M16: 2 horas | N16: Bajo reserva | O16: Arte en Carlota: Desayuno + clase: $65.00 Brunch + clase: $88.00 Menú Lounge + clase: $82.00 Clase:$55.00 Clase de cocina: $45.00 Cata de chocolate y gin: $45.00 | R16: https://carlota.ec/ (+593) 99 922 3336 / (+593) 98 495 2689
A17: 016 | B17: ACTIVO | C17: =CONCATENATE(VLOOKUP($D17,CODIFICACIÓN_DPA!$A$2:$B$66,2,FALSE),VLOOKUP($G17,CODIFICACIÓN_DPA!$D$2:$E$6,2,FALSE),CONCATENATE(VLOOKUP($E17,CODIFICACIÓN_DPA!$G$2:$H$3,2,FALSE),VLOOKUP($F17,CODIFICACIÓN_DPA!$J$2:$K$10,2,FALSE)),A17) -> 170179GA0208016 | D17: PUEMBO | E17: RURAL | F17: Valle de Tumbaco | G17: GASTRONÓMICO | H17: Páramo Brauhaus | I17: La Cervecería Páramo ofrece una experiencia única para los amantes de la cerveza artesanal. Los visitantes tienen la oportunidad de conocer de cerca el proceso de elaboración de la cerveza artesanal durante una visita a su fábrica. Además, pueden disfrutar de una emocionante cata de cerveza artesanal, donde pueden deleitarse con una variedad de sabores y estilos únicos. Esta experiencia brinda una mirada íntima al mundo de la cerveza artesanal y promete satisfacer los paladares más exigentes con sus deliciosas creaciones. | J17: Puembo- Santa Rosa y, Av. Oswaldo Guayasamín, Quito 170905 | K17: -0.20718541 | L17: -78.365028 | M17: 1 hora 30 minutos | N17: Lunes a Viernes 08:00 – 17:00 Páramo Biergarten: Viernes: 12:00 – 22:00 Sábado y domingo: 10:00 – 17:00 | O17: $15.00 por persona | P17: 20 a 50 personas | R17: (02) 389 5435 (+593) 99 271 5573 / (+593) 99 306 9654 Judith Bauer.
A18: 017 | B18: ACTIVO | C18: =CONCATENATE(VLOOKUP($D18,CODIFICACIÓN_DPA!$A$2:$B$66,2,FALSE),VLOOKUP($G18,CODIFICACIÓN_DPA!$D$2:$E$6,2,FALSE),CONCATENATE(VLOOKUP($E18,CODIFICACIÓN_DPA!$G$2:$H$3,2,FALSE),VLOOKUP($F18,CODIFICACIÓN_DPA!$J$2:$K$10,2,FALSE)),A18) -> 170177GA0204017 | D18: POMASQUI | E18: RURAL | F18: Parroquias Equinocciales | G18: GASTRONÓMICO | H18: Cervecería Quiteña Craft Beer Company | I18: Cervecería Quiteña Craft Beer Company ofrece una experiencia única de maridaje entre cerveza artesanal y embutidos también artesanales, elaborados en el lugar con dedicación y pasión. Los visitantes tienen la oportunidad de sumergirse en la historia y el proceso de producción de la cerveza, mediante un recorrido por las instalaciones de la planta cervecera, donde se revelan los secretos de la elaboración de esta bebida milenaria. Además, se ofrece una degustación completa de todos los tipos de cerveza producidos, permitiendo a los participantes explorar una amplia gama de sabores y estilos, mientras aprenden sobre las características únicas de cada una. Este encuentro con la artesanía cervecera y la tradición culinaria local promete deleitar los sentidos y brindar una experiencia memorable para los amantes de la buena comida y la cerveza de calidad. | J18: Av. Manuel Córdova Galarza S4-187 y Marcelina Nolivos. 300 m más al norte del Colegio Francés. Junto a Helados Avelina. | K18: -0.057720144 | L18: -78.457537 | M18: 1 hora | N18: Bajo reserva | O18: $ 15.00 por persona | P18: Mínimo 6 pax (incluido guía) en un horario fuera de lo normal Máximo 40 pax (incluido guía) | R18: andres.eraso@gmail.com https://www.facebook.com/CerveceriaQuiteña (+593) 99 552 8651
A19: 018 | B19: ACTIVO | C19: =CONCATENATE(VLOOKUP($D19,CODIFICACIÓN_DPA!$A$2:$B$66,2,FALSE),VLOOKUP($G19,CODIFICACIÓN_DPA!$D$2:$E$6,2,FALSE),CONCATENATE(VLOOKUP($E19,CODIFICACIÓN_DPA!$G$2:$H$3,2,FALSE),VLOOKUP($F19,CODIFICACIÓN_DPA!$J$2:$K$10,2,FALSE)),A19) -> 170180GA0204018 | D19: SAN ANTONIO | E19: RURAL | F19: Parroquias Equinocciales | G19: GASTRONÓMICO | H19: Santana Brewing Company | I19: Santana Brewing Company, establecida en 2012, es un destino imprescindible para los amantes de la cerveza artesanal. Ofrecen una experiencia única donde los visitantes pueden disfrutar de una cata de cervezas artesanales en armonía con una selección de platos nacionales contemporáneos. Cada plato está cuidadosamente elaborado para realzar y complementar los sabores de las cervezas, brindando así una experiencia gastronómica excepcional. En Santana Brewing Company, la pasión por la cerveza de calidad y la cocina local se fusionan para crear una experiencia memorable para los paladares más exigentes. | J19: Mitad del Mundo | K19: 0.001039806 | L19: -78.451559 | M19: 1 hora | N19: Miércoles a Domingo 12h00 a 17h00 | O19: $15.00 por persona | P19: Máximo 10 pax | R19: (+593) 96 125 3653 info@santanabc.com
A20: 019 | B20: ACTIVO | C20: =CONCATENATE(VLOOKUP($D20,CODIFICACIÓN_DPA!$A$2:$B$66,2,FALSE),VLOOKUP($G20,CODIFICACIÓN_DPA!$D$2:$E$6,2,FALSE),CONCATENATE(VLOOKUP($E20,CODIFICACIÓN_DPA!$G$2:$H$3,2,FALSE),VLOOKUP($F20,CODIFICACIÓN_DPA!$J$2:$K$10,2,FALSE)),A20) -> 170103GA0101019 | D20: CENTRO HISTÓRICO | E20: URBANO | F20: Centro Histórico | G20: GASTRONÓMICO | H20: Heladería Dulce Jesús Mío | I20: La Heladería Dulce Jesús Mío ofrece una experiencia única para los amantes del helado, donde la degustación se transforma en un viaje por la tradición y la innovación. Reconocida por su impresionante variedad de helados artesanales, aquí se combina la creatividad contemporánea con la técnica ancestral del helado de paila, elaborado de forma tradicional y con ingredientes frescos. Durante la visita, los anfitriones comparten la historia detrás de cada creación, invitando a probar propuestas exóticas como morocho, colada morada, canelazo o mojito, que sorprenden por su autenticidad y equilibrio. Más que un lugar para disfrutar un postre, Dulce Jesús Mío es una celebración del ingenio local y de la riqueza de la cultura gastronómica quiteña, donde cada cucharada evoca dulzura, identidad y alegría. | J20: Morales OE 325 170130 Quito, Ecuador | K20: -0.22401415 | L20: -78.514053 | M20: 1 hora | N20: Todos los días de 10h00 a 18h00 | O20: Depende del recipiente para servirse. $1.00 - $3.50 | P20: Hasta 32 personas | R20: (+593) 98 408 5720
A21: 020 | B21: ACTIVO | C21: =CONCATENATE(VLOOKUP($D21,CODIFICACIÓN_DPA!$A$2:$B$66,2,FALSE),VLOOKUP($G21,CODIFICACIÓN_DPA!$D$2:$E$6,2,FALSE),CONCATENATE(VLOOKUP($E21,CODIFICACIÓN_DPA!$G$2:$H$3,2,FALSE),VLOOKUP($F21,CODIFICACIÓN_DPA!$J$2:$K$10,2,FALSE)),A21) -> 170123GA0102020 | D21: MARISCAL SUCRE | E21: URBANO | F21: La Mariscal | G21: GASTRONÓMICO | H21: Cherusker | I21: Cherusker, desde su fundación en 2011, se ha dedicado a elaborar cervezas artesanales que rinden homenaje a los estilos clásicos alemanes y europeos. Siguiendo la icónica ley de pureza alemana "Reinheitsgebot" de 1516, diversifican detalles y texturas para adaptarse al gusto nacional, logrando así una perfecta fusión entre la tradición cervecera y el encanto del Ecuador. En Cherusker, los visitantes tienen la oportunidad de vivir una experiencia única al degustar su variedad de cervezas artesanales, explorando los distintos matices y sabores que ofrecen. | J21: Joaquín Pinto E7-85 y Diego de Almagro | K21: -0.2035489 | L21: -78.490986 | M21: Depende del grupo | N21: Lunes 16h00 a 00h00 Martes y miercoles 13h00 a 00h00 Jueves a sábado de 12h00 a 02h00 | O21: Variados | P21: Se adapta a la necesidad | Q21: Mayores de 18 años | R21: (02) 6012 142 reservaciones.uio@cherusker.com
A22: 021 | B22: ACTIVO | C22: =CONCATENATE(VLOOKUP($D22,CODIFICACIÓN_DPA!$A$2:$B$66,2,FALSE),VLOOKUP($G22,CODIFICACIÓN_DPA!$D$2:$E$6,2,FALSE),CONCATENATE(VLOOKUP($E22,CODIFICACIÓN_DPA!$G$2:$H$3,2,FALSE),VLOOKUP($F22,CODIFICACIÓN_DPA!$J$2:$K$10,2,FALSE)),A22) -> 170177GA0204021 | D22: POMASQUI | E22: RURAL | F22: Parroquias Equinocciales | G22: GASTRONÓMICO | H22: Casa Agave Ecuador | I22: Casa Agave Ecuador ofrece una experiencia única que combina naturaleza, cultura y degustación. Los visitantes tienen la oportunidad de explorar su impresionante jardín botánico acompañados de un guía especializado, descubriendo la diversidad y belleza de las plantas de agave. Además, podrán sumergirse en la historia y el proceso de elaboración de los productos de agave en el museo de la casa. Para culminar la experiencia, los invitados pueden deleitarse con la degustación de "mishki", una bebida tradicional, y disfrutar de una cata de cócteles preparados con maestría por el equipo de la casa. | J22: Quishuar N3-29 y Casitagua - Pomasqui | K22: -0.048083003 | L22: -78.455766 | M22: 1 hora 30 minutos | N22: Martes a domingo 11h00 a 17h00 Recorridos 11h30 13h30 15h00 17h00 | O22: Entrada al museo, jardín botánico, cata de mishke Para público general $17.00 Para agencia; $15.00 Precio no incluye IVA | R22: Belén Simbaña Llamar (+593) 99 831 6455 casaagaveoficial@gmail.com m.me/agavemitaddelmundo http://agavespiritecuador.com
A23: 022 | B23: ACTIVO | C23: =CONCATENATE(VLOOKUP($D23,CODIFICACIÓN_DPA!$A$2:$B$66,2,FALSE),VLOOKUP($G23,CODIFICACIÓN_DPA!$D$2:$E$6,2,FALSE),CONCATENATE(VLOOKUP($E23,CODIFICACIÓN_DPA!$G$2:$H$3,2,FALSE),VLOOKUP($F23,CODIFICACIÓN_DPA!$J$2:$K$10,2,FALSE)),A23) -> 170103GA0101022 | D23: CENTRO HISTÓRICO | E23: URBANO | F23: Centro Histórico | G23: GASTRONÓMICO | H23: Yumbos Chocolate | I23: Chocolate Yumbo ofrece una experiencia auténtica y deliciosa para los amantes del chocolate. Su chocolate puro, producido a mano y sin conservantes ni saborizantes artificiales, proviene de lotes de cacao seleccionado de variedades aromáticas, como el Nacional Fino y de Aroma, característico de Ecuador. En este espacio, los visitantes pueden sumergirse en el proceso de tostado y elaboración del chocolate desde cero, aprendiendo sobre las técnicas tradicionales utilizadas antiguamente y degustando su exquisito chocolate caliente acompañado de un brownie elaborado con el más puro chocolate. Además, Chocolate Yumbo ofrece actividades como el "Festín de Chocolate", una experiencia de degustación donde los participantes pueden disfrutar de una selección de chocolates acompañados de una copa de vino, para una experiencia verdaderamente indulgente. | J23: Quito: Calle Sebastián de Benalcázar N 2-26 Segundo Piso (Frente a la Iglesia San Francisco) Mindo: Avenida Quito (a 1 cuadra de la plaza central de Mindo) | K23: -0.22094148 | L23: -78.514713 | M23: 1 hora | N23: QUITO: 09h30 a 19h00 MINDO: Tours disponibles a partir de las 10h00 a 22h00 todos los días de la semana. | O23: - Mindo: Tour Chocolate Experiencia Tradicional : $10.00 Tour Chocolate Experiencia Ancestral: $15.00 - Quito: Tour Chocolate Experiencia Tradicional : $10.00 Tour Chocolate Experiencia Ancestral: $15.00 - Quito: Degustación chocolate caliente 4 oz: $4.00 Degustación chocolate caliente 6 oz: $6.00 Cata de vino: $12.00 Cata de Cerveza: $12.00 Productos: -Barras chocolate: $6.50 -Polvo de cacao: $12.00 -Syrup de cacao: $8.00 -Salsa BBQ de chocolate: $8.00 -Jarabe de jengibre: $7.00 -Té de cacao: $6.50 -Pastillas de chocolate al 100%: $15.00 -Almendra de cacao la (oz) bajo pedido : $1.00 -Mini barras: $1.50 Los precios incluyen IVA | R23: Claudia Ponce (+593) 98 000 4417 Facebook: @YumbosChocolate www.yumboschocolate.com contact@yumboschocolate.com instagram: yumboschocolate.ec
A24: 023 | B24: ACTIVO | C24: =CONCATENATE(VLOOKUP($D24,CODIFICACIÓN_DPA!$A$2:$B$66,2,FALSE),VLOOKUP($G24,CODIFICACIÓN_DPA!$D$2:$E$6,2,FALSE),CONCATENATE(VLOOKUP($E24,CODIFICACIÓN_DPA!$G$2:$H$3,2,FALSE),VLOOKUP($F24,CODIFICACIÓN_DPA!$J$2:$K$10,2,FALSE)),A24) -> 170103GA0101023 | D24: CENTRO HISTÓRICO | E24: URBANO | F24: Centro Histórico | G24: GASTRONÓMICO | H24: República del Cacao | I24: Se puede encontrar los productos del Chocolate Boutique en donde se ofrece todas las presentaciones de barras y regalos de República del Cacao. Por otro lado está el Rincón del Emprendedor, proyecto que apoya a emprendedores que realizan productos con chocolate o productos inspirados en el cacao. También está el Taller del Cacao ejecutado por el chef Santiago Cueva, en donde se ofrecen bombones únicos realizados con chocolate de cacao fino y repostería de muy alta calidad; todos estos productos se realizan en el nuevo Laboratorio de República del Cacao que también se encuentra en el local del Centro Histórico. Finalmente los clientes pueden visitar el Museo del Cacao en donde pueden aprender sobre él la historia del cacao en el Ecuador, y el proceso del mismo. | J24: Venezuela N5-45 y Chile, a 15 metros de la Plaza Grande. | K24: -0.21956107 | L24: -78.511079 | M24: 1hora 30 minutos | N24: 08h30 a 19h30 | O24: $15.00 por personas. Previa reserva de 24 horas | P24: Máximo 20 pax | Q24: Personas alérgicas al chocolate | R24: (+593) 98 346 3290 https://republicadelcacao.com/pages/stores
A25: 024 | B25: ACTIVO | C25: =CONCATENATE(VLOOKUP($D25,CODIFICACIÓN_DPA!$A$2:$B$66,2,FALSE),VLOOKUP($G25,CODIFICACIÓN_DPA!$D$2:$E$6,2,FALSE),CONCATENATE(VLOOKUP($E25,CODIFICACIÓN_DPA!$G$2:$H$3,2,FALSE),VLOOKUP($F25,CODIFICACIÓN_DPA!$J$2:$K$10,2,FALSE)),A25) -> 170112GA0103024 | D25: IÑAQUITO | E25: URBANO | F25: Centro Norte | G25: GASTRONÓMICO | H25: Mercado Iñaquito (Mercado La Carolina) | I25: La experiencia gastronómica en el Mercado Iñaquito, también conocido como Mercado La Carolina, es verdaderamente diversa y vibrante. A pesar de mantener su enfoque en la venta de productos de primera necesidad a precios accesibles, el mercado ofrece una amplia variedad de opciones culinarias que reflejan la riqueza y la autenticidad de la cocina local. Con locales adyacentes que ofrecen desde platos típicos ecuatorianos hasta opciones internacionales, los visitantes pueden deleitarse con una verdadera aventura gastronómica mientras exploran los pasillos del mercado. Desde sabores tradicionales hasta innovadoras propuestas culinarias, el Mercado Iñaquito es un destino imprescindible para los amantes de la comida que buscan una experiencia auténtica y satisfactoria. | J25: Calle Iñaquito y Pereira | K25: -0.17181432 | L25: -78.48627 | M25: 1 hora | N25: Lunes a Domingo 07h00 a 18h00 | O25: Depende del grupo y actividad | P25: Máximo 20 pax | R25: (+593) 99 468 1378
A26: 025 | B26: ACTIVO | C26: =CONCATENATE(VLOOKUP($D26,CODIFICACIÓN_DPA!$A$2:$B$66,2,FALSE),VLOOKUP($G26,CODIFICACIÓN_DPA!$D$2:$E$6,2,FALSE),CONCATENATE(VLOOKUP($E26,CODIFICACIÓN_DPA!$G$2:$H$3,2,FALSE),VLOOKUP($F26,CODIFICACIÓN_DPA!$J$2:$K$10,2,FALSE)),A26) -> 170103GA0101025 | D26: CENTRO HISTÓRICO | E26: URBANO | F26: Centro Histórico | G26: GASTRONÓMICO | H26: Mercado Central | I26: La experiencia gastronómica en el Mercado Central es una inmersión en las tradiciones culinarias de la capital. Con el 60% de los comerciantes dedicados a ofrecer platos que son emblemáticos de la cultura local, los visitantes pueden disfrutar de una variedad de delicias que incluyen la auténtica colada de churos, el reconfortante caldo bille, el sabroso caldo de guagrasinga y las deliciosas corvinas preparadas de diversas maneras. Esta diversidad de sabores y platos refleja la riqueza gastronómica de la región y ofrece a los comensales una experiencia auténtica y memorable en el corazón del Mercado Central. | J26: Av. Pichincha entre Manabí y Esmeraldas | K26: -0.21970285 | L26: -78.507084 | N26: lunes a domingo 07h00 - 15h00 | O26: Depende del grupo | Q26: Se consulta sobre el plato a degustar dado que son platos poco comunes. Anticipar alergías al maní, mariscos, intolerantes a la lactosa. | R26: (+593) 99 891 0022
A27: 026 | B27: ACTIVO | C27: =CONCATENATE(VLOOKUP($D27,CODIFICACIÓN_DPA!$A$2:$B$66,2,FALSE),VLOOKUP($G27,CODIFICACIÓN_DPA!$D$2:$E$6,2,FALSE),CONCATENATE(VLOOKUP($E27,CODIFICACIÓN_DPA!$G$2:$H$3,2,FALSE),VLOOKUP($F27,CODIFICACIÓN_DPA!$J$2:$K$10,2,FALSE)),A27) -> 170175NA0208026 | D27: PIFO | E27: RURAL | F27: Valle de Tumbaco | G27: NATURAL | H27: Hacienda Jimenita Naturhotel & Reserva de Vida Silvestre | I27: La Hacienda Jimenita Naturhotel & Reserva de Vida Silvestre ofrece una experiencia única donde la tranquilidad se fusiona con la exuberante naturaleza. Los huéspedes pueden sumergirse en un entorno de serenidad y descubrir la magia de la vida silvestre mientras participan en una variedad de actividades emocionantes y educativas. Desde la observación de aves en la reserva natural hasta la exploración de senderos históricos y la participación en actividades de siembra y cosecha de alimentos orgánicos, cada momento en la hacienda ofrece la oportunidad de conectarse con la tierra y aprender sobre la rica cultura ecológica de la región. Con opciones como clases de cocina, paseos a caballo por los Andes y tours hacia Papallacta y el Parque Nacional Antisana, la Hacienda Jimenita brinda una experiencia inolvidable para los amantes de la naturaleza y la aventura. | J27: Barrio Andrango Pasaje 2, Casa 19, Parroquia Pifo | K27: -0.23454809 | L27: -78.349949 | M27: Observación de aves: 2 horas Sendero Histórico: sin restricción Alimenta a las llamas: sin restricción Siembre y Cosecha: 06h00 a 17h00 Clases de cocina: 1 a 2 horas Paseo a Caballo en los Andes: 5 horas Tour de la Rosa Gigante: 2 horas Tour del Cóndor: 5 horas | N27: Observación de aves: 07h00 a 10h00 y de 14:00 a 18:00 Sendero Histórico: Cualquier hora Alimenta a las llamas: 06h00 a 20h00 Siembre y Cosecha: 06h00 a 17h00 Clases de cocina: 06h00 a 20h00 Paseo a Caballo en los Andes: parte desde la hacienda a las 08h00 y 09h00 Tour de la Rosa Gigante: parte desde la hacienda a las 08h00 y 09h00 Tour del Cóndor: parte desde la hacienda a las 06h00 a 07h00 | O27: Observación de aves: $60.00 Sendero Histórico: No tiene costo, debe estar hospedado Alimenta a las llamas: Canasta de alimentos $5.00, debe estar hospedado Siembre y Cosecha: No tiene costo, debe estar hospedado Clases de cocina: $50.00 a $80.00 inlcuye todos los utensillos e insumos Paseo a Caballo en los Andes: $140.00 Tour de la Rosa Gigante: $60.00 Tour del Cóndor: $180.00 Precios no incluyen IVA | P27: Entre 10 a 12 participantes, en las actividades que son necesarios guías o chef | R27: Karina Morejón (+593) 95 860 4606 (+593) 99 923 8048 info@jimenita.com ventas@jimenita.com
A28: 027 | B28: ACTIVO | C28: =CONCATENATE(VLOOKUP($D28,CODIFICACIÓN_DPA!$A$2:$B$66,2,FALSE),VLOOKUP($G28,CODIFICACIÓN_DPA!$D$2:$E$6,2,FALSE),CONCATENATE(VLOOKUP($E28,CODIFICACIÓN_DPA!$G$2:$H$3,2,FALSE),VLOOKUP($F28,CODIFICACIÓN_DPA!$J$2:$K$10,2,FALSE)),A28) -> 170175NA0208027 | D28: PIFO | E28: RURAL | F28: Valle de Tumbaco | G28: NATURAL | H28: Sacha Rose | I28: Se caracterizan por tener las rosas más grandes del mundo es la marca registrada de esta florícola. Se caracterizan por constantes en la calidad, el compromiso con la comunidad, la productividad sostenible y el compromiso con el medio ambiente. Brinda la experiencia de Tour guiados para turistas nacionales y extranjeros y la visita al invernadero donde están las rosas, explicación de la productividad, tipo de cultivo, post cosecha, café con galletas de cortesía. | J28: Vía Pifo-Papallacta Km 8 | K28: -0.26947666 | L28: -78.285611 | M28: 45 minutos | N28: 07h00 a 15h00 | O28: Tours guiados $10.00 + IVA | P28: Mínimo 5 turistas | Q28: Los días sábado y domingo; para brindar la experiencia, debe haber mínimo 5 turistas, de lunes a viernes no es inconveniente la cantidad de turistas. Siempre hacer reserva con 3 días de anticipación, al correo auxiliar@sacharose.com o al número +593 99 833 8944. Los guías hablan español, en caso de necesitar un guía que hable inglés, el dueño podría ayudar con la experiencia | R28: Ing. Guillermo Bustamante Teléfono: (02) 450 8929 Celular: (+593) 99 833 8944 VENTAS: Hemerson Salazar Correo: Skype sales_sacha Instagram: @sacharoseec Mail: gerencia@sacharose.com Ana Cajamarca auxiliar@sacharose.com
A29: 028 | B29: ACTIVO | C29: =CONCATENATE(VLOOKUP($D29,CODIFICACIÓN_DPA!$A$2:$B$66,2,FALSE),VLOOKUP($G29,CODIFICACIÓN_DPA!$D$2:$E$6,2,FALSE),CONCATENATE(VLOOKUP($E29,CODIFICACIÓN_DPA!$G$2:$H$3,2,FALSE),VLOOKUP($F29,CODIFICACIÓN_DPA!$J$2:$K$10,2,FALSE)),A29) -> 170172NA0205028 | D29: PACTO | E29: RURAL | F29: Chocó Andino | G29: NATURAL | H29: Pambiliño Bosque escuela. | I29: Pambiliño Bosque Escuela ofrece una experiencia inmersiva en el exuberante bosque lluvioso del Chocó Andino, situado a 550 metros sobre el nivel del mar, en las afueras de Quito. Este espacio único presenta una biodiversidad impresionante que está bajo amenaza, brindando la oportunidad de participar en el turismo vivencial. Los visitantes pueden explorar el bosque con una variedad de actividades flexibles, que incluyen cursos y talleres sobre agricultura sostenible, descubrimiento sensorial en el bosque, laboratorios de alimentos, así como también opciones de turismo vivencial como gastronomía y senderismo guiado. Con opciones de hospedaje y alimentación disponibles dentro de la finca Pambiliño, los visitantes pueden diseñar una experiencia a medida que se adapte a sus intereses y preferencias. | J29: Vía a Mashpi. 53 JR+Q45, Quito | K29: 0.18211233 | L29: -78.909785 | M29: Sendero Regeneración Natural: 2 horas Gastronomía del Bosque: 4 horas Sendero Eco Restauración: 3 horas Aves, fauna y flora: 2 horas Baño en el río: tiempo libre | N29: Bajo reserva | O29: Sendero Regeneración Natural: $10.00 Gastronomía del Bosque:$20.00 Sendero Eco Restauración:$15.00 Aves, fauna y flora: $10.00 Baño en el río: aporte voluntario | P29: Se adapta a la necesidad del grupo. | R29: https://www.pambilino.org/turismo-vivencial
A30: 029 | B30: INACTIVO | C30: =CONCATENATE(VLOOKUP($D30,CODIFICACIÓN_DPA!$A$2:$B$66,2,FALSE),VLOOKUP($G30,CODIFICACIÓN_DPA!$D$2:$E$6,2,FALSE),CONCATENATE(VLOOKUP($E30,CODIFICACIÓN_DPA!$G$2:$H$3,2,FALSE),VLOOKUP($F30,CODIFICACIÓN_DPA!$J$2:$K$10,2,FALSE)),A30) -> 170103CU0101029 | D30: CENTRO HISTÓRICO | E30: URBANO | F30: Centro Histórico | G30: CULTURAL | H30: Convento de San Agustín | I30: En pleno Centro Histórico, el Convento de San Agustín resguarda siglos de historia, arte y espiritualidad. Este majestuoso conjunto arquitectónico, construido entre los siglos XVI y XVII, alberga una de las iglesias más bellas de Quito y el Museo Miguel de Santiago, donde se conservan lienzos y esculturas de la Escuela Quiteña. Habitualmente abierto para recorridos por la iglesia principal, los claustros y las salas que guardan verdaderas joyas del arte barroco. En ocasiones especiales, se habilitan visitas ampliadas que incluyen patios, torres o espacios internos, ofreciendo una mirada exclusiva a este tesoro patrimonial. Más que un monumento religioso, el Convento de San Agustín es un encuentro con la esencia de Quito: un lugar donde el silencio, la belleza y la historia se funden para inspirar a quienes lo recorren. No se olvide de probar sus productos como licor canario, galletas, pasteles frescos, o agua de rosas. | J30: Guayaquil N5-59 y Chile | K30: -0.22135 | L30: -78.51298 | M30: Depende del recorrido | N30: Bajo reserva | O30: Depende del grupo
A31: 030 | B31: ACTIVO | C31: =CONCATENATE(VLOOKUP($D31,CODIFICACIÓN_DPA!$A$2:$B$66,2,FALSE),VLOOKUP($G31,CODIFICACIÓN_DPA!$D$2:$E$6,2,FALSE),CONCATENATE(VLOOKUP($E31,CODIFICACIÓN_DPA!$G$2:$H$3,2,FALSE),VLOOKUP($F31,CODIFICACIÓN_DPA!$J$2:$K$10,2,FALSE)),A31) -> 170154GA0205030 | D31: CALACALÍ | E31: RURAL | F31: Chocó Andino | G31: GASTRONÓMICO | H31: LA CUCHARA ORGÁNICA | I31: La Cuchara Orgánica es mucho más que un restaurante, es un espacio comprometido con la revalorización de saberes ancestrales, el comercio justo y la cocina saludable y consciente. Ofrecen una variedad de experiencias gastronómicas únicas que van desde talleres especializados de cocina saludable con Mamita Pastora, donde se enseñan platos tradicionales ecuatorianos y recetas con plantas no convencionales del Chocó Andino, hasta experiencias de aprendizaje y degustación de productos como la savia del agave andino y productos derivados. También ofrecen catas y elaboración de infusiones, bebidas, barras de chocolate y bombones con café y cacao del Chocó Andino. Los domingos, brindan actividades educativas y divertidas para niños con clases de cocina y juegos tradicionales. Además, ofrecen tours educativos por su pequeña huerta andina y por la localidad de Calacalí, donde se visitan monumentos, se degustan dulces tradicionales y se participa en rituales andinos de agradecimiento. Estas experiencias proporcionan una conexión profunda con la cultura, la naturaleza y la gastronomía de la región. | J31: Juan José Flores E536 y pasaje Luis Calderón, Calacalí, Ecuador | K31: -0.0005587098 | L31: -78.509011 | M31: Depende del recorrido | N31: Miercoles a domingo 10h00 a 17h00 | O31: Experiencia cocinando con Mamita Pastora: depende de la activida que se elija si especializada o express. Experiencia Tzawar: USD 7 Experiencia Café y Cacao del Chocó Andino: USD 7 Experiencia Wawas en La Cuchara: actividad gratuita con aporte voluntario. | P31: Mínimo 10 personas, máximo 20. | R31: 969006237
A32: 031 | B32: ACTIVO | C32: =CONCATENATE(VLOOKUP($D32,CODIFICACIÓN_DPA!$A$2:$B$66,2,FALSE),VLOOKUP($G32,CODIFICACIÓN_DPA!$D$2:$E$6,2,FALSE),CONCATENATE(VLOOKUP($E32,CODIFICACIÓN_DPA!$G$2:$H$3,2,FALSE),VLOOKUP($F32,CODIFICACIÓN_DPA!$J$2:$K$10,2,FALSE)),A32) -> 170176AV0207031 | D32: PÍNTAG | E32: RURAL | F32: Valle de los Chillos | G32: AVENTURA | H32: Laguna de secas | I32: La Laguna de Secas ofrece una experiencia natural única, ideal para disfrutar en familia y sumergirse en la belleza del entorno. Este espacio natural permite realizar una variedad de actividades recreativas, como camping, pesca deportiva y excursiones, que brindan la oportunidad de conectar con la naturaleza y crear recuerdos inolvidables. Ya sea relajándose junto a la laguna o explorando los senderos circundantes, los visitantes pueden disfrutar de momentos de tranquilidad y aventura en este hermoso entorno natural. | J32: Se toma la vía pavimentada que sube desde Pintag a la Reserva Ecológica Antisana, unos 12 kilómetros y se podrá observar a la izquierda La Laguna de Secas. | K32: -0.44569525 | L32: -78.327904 | M32: Pintag - Mirador Lagunas de Secas 30 min Vía al Antisana - Lagunas de Secas 1 hora y 20 minutos | N32: Lunes a Domingo Hora de Ingreso 07h00 a 15h00 Hora de Salida 18h00 | O32: Gratuito | P32: Depende del grupo | Q32: No cazar No mascotas
A33: 032 | B33: INACTIVO | C33: =CONCATENATE(VLOOKUP($D33,CODIFICACIÓN_DPA!$A$2:$B$66,2,FALSE),VLOOKUP($G33,CODIFICACIÓN_DPA!$D$2:$E$6,2,FALSE),CONCATENATE(VLOOKUP($E33,CODIFICACIÓN_DPA!$G$2:$H$3,2,FALSE),VLOOKUP($F33,CODIFICACIÓN_DPA!$J$2:$K$10,2,FALSE)),A33) -> 170175AV0208032 | D33: PIFO | E33: RURAL | F33: Valle de Tumbaco | G33: AVENTURA | H33: Laguna de Loreto | I33: La Laguna de Loreto, ubicada dentro del Parque Nacional Cayambe-Coca, ofrece una experiencia incomparable para los amantes de la naturaleza y los aventureros. Este impresionante paisaje es un lugar ideal para acampar y realizar excursiones, permitiendo a los visitantes sumergirse en la belleza natural de la región. Con su entorno pintoresco y su atmósfera serena, la Laguna de Loreto invita a los viajeros a desconectarse del bullicio de la vida cotidiana y conectarse con la tranquilidad y la majestuosidad de la naturaleza. | J33: Se empieza desde la población de Papallacta, se toma el desvío hacia las termas de Papallacta y luego al Parque Nacional Cayambe Coca. Ahí se deja el vehículo y se debe ir caminando o en bicicleta hasta la laguna. | K33: -0.30986655 | L33: -78.146516 | M33: Termas de Papallacta - Contol de la Reserva 17 minutos Control de la Reserva - Laguna de Loreto 15 minutos | N33: Martes a Domingo Horario de Ingreso 08h00 a 14h00 Hora de Salida 17h00 | O33: Gratuito | P33: Por día 400 personas | Q33: No botar basura No mascotas
A34: 033 | B34: ACTIVO | C34: =CONCATENATE(VLOOKUP($D34,CODIFICACIÓN_DPA!$A$2:$B$66,2,FALSE),VLOOKUP($G34,CODIFICACIÓN_DPA!$D$2:$E$6,2,FALSE),CONCATENATE(VLOOKUP($E34,CODIFICACIÓN_DPA!$G$2:$H$3,2,FALSE),VLOOKUP($F34,CODIFICACIÓN_DPA!$J$2:$K$10,2,FALSE)),A34) -> 170176AV0207033 | D34: PÍNTAG | E34: RURAL | F34: Valle de los Chillos | G34: AVENTURA | H34: Laguna de Tipo Pugro | I34: La Laguna de Tipo Pugro es un destino turístico de fácil acceso que cautiva con su belleza natural y su historia geológica. Formada principalmente por erupciones secundarias del volcán Antisana y alimentada por el represamiento del río Chacauco, esta laguna ofrece un paisaje impresionante y una atmósfera tranquila. Los visitantes pueden disfrutar de actividades como la pesca deportiva, emocionantes excursiones y la oportunidad de acampar en sus alrededores, brindando una experiencia inolvidable en contacto directo con la naturaleza. | J34: Laguna Tipopugro, Via Antisana, Quito | K34: -0.44751175 | L34: -78.33664 | M34: 1 hora 30 minutos | N34: Miércoles a Domingo Hora de Ingreso 07h00 a 15h00 Hora de Salida 18h00 | O34: Costo de Entrada por Persona: $3 | P34: Depende del grupo | Q34: No botar basura No mascotas
A35: 034 | B35: ACTIVO | C35: =CONCATENATE(VLOOKUP($D35,CODIFICACIÓN_DPA!$A$2:$B$66,2,FALSE),VLOOKUP($G35,CODIFICACIÓN_DPA!$D$2:$E$6,2,FALSE),CONCATENATE(VLOOKUP($E35,CODIFICACIÓN_DPA!$G$2:$H$3,2,FALSE),VLOOKUP($F35,CODIFICACIÓN_DPA!$J$2:$K$10,2,FALSE)),A35) -> 170154AV0204034 | D35: CALACALÍ | E35: RURAL | F35: Parroquias Equinocciales | G35: AVENTURA | H35: Reserva Geobotánica El Pululahua | I35: La Reserva Geobotánica El Pululahua es una joya natural única, siendo la única área protegida con esta designación en Ecuador. Este lugar ofrece una experiencia excepcional para los amantes de la naturaleza, donde pueden sumergirse en la biodiversidad y la belleza escénica de la región. Además de ser un refugio para una gran variedad de flora y fauna, la reserva proporciona un entorno ideal para actividades al aire libre, como el camping y las emocionantes excursiones, permitiendo a los visitantes conectarse íntimamente con este paisaje volcánico impresionante. | J35: Ingreso por Ventanillas. Por la carretera Quito – Calacalí. A 6 kilómetros del Monumento a la Mitad del Mundo, en el sector de Caspigasí (hay una gasolinera en el sector), se desvía hacia la derecha y se sigue 1,2 kilómetros hasta el mirador. Ingreso por Moraspungo. Por la vía Quito – Calacalí se continúa 8 kilómetros después del sector de Caspigasí, hasta llegar a una segunda gasolinera. A 500 metros se encuentra una vía de tierra a mano derecha. Tras 3 kilómetros se llega al control de Moraspungo. Desde este sector toma 30 minutos llegar a la caldera por una vía con muchas curvas y de fuerte pendiente que cubre una extensión de 12 kilómetros. | K35: -0.025227897 | L35: -78.482745 | M35: Trekking y senderismo: 2 a 5 horas Caminata de 1 día: 6 horas Recorrido Completo: 5 horas | N35: Todos los días de 08h00 a 17h00 | O35: Gratuito | P35: Depende del grupo | Q35: No cazar No mascotas | R35: (02) 239-6543
A36: 035 | B36: ACTIVO | C36: =CONCATENATE(VLOOKUP($D36,CODIFICACIÓN_DPA!$A$2:$B$66,2,FALSE),VLOOKUP($G36,CODIFICACIÓN_DPA!$D$2:$E$6,2,FALSE),CONCATENATE(VLOOKUP($E36,CODIFICACIÓN_DPA!$G$2:$H$3,2,FALSE),VLOOKUP($F36,CODIFICACIÓN_DPA!$J$2:$K$10,2,FALSE)),A36) -> 170172AV0205035 | D36: PACTO | E36: RURAL | F36: Chocó Andino | G36: AVENTURA | H36: San José de Mashpi | I36: San José de Mashpi ofrece una experiencia auténtica en un entorno natural espectacular. Esta pequeña comunidad es un destino ideal para los amantes de la aventura y la naturaleza. Rodeada de exuberante vegetación y ubicada junto al río que lleva el mismo nombre, San José de Mashpi brinda la oportunidad de realizar emocionantes excursiones, explorar la zona en bicicleta y disfrutar del campismo en un ambiente sereno y tranquilo. Con su belleza natural y su ambiente acogedor, esta comunidad es el lugar perfecto para desconectar y disfrutar de la vida al aire libre. | J36: Desde Quito tomar un autobús desde el Terminal Terrestre de Carcelén hacia Pedro Vicente Maldonado, allí tomar la línea rural Mashpi – Pachijal. | K36: 0.1756544 | L36: -78.907339 | M36: 2 horas 30 minutos hasta 3 horas | N36: Todos los días | O36: Depende del grupo | P36: Depende del grupo | Q36: No basura No mascotas
A37: 036 | B37: INACTIVO | C37: =CONCATENATE(VLOOKUP($D37,CODIFICACIÓN_DPA!$A$2:$B$66,2,FALSE),VLOOKUP($G37,CODIFICACIÓN_DPA!$D$2:$E$6,2,FALSE),CONCATENATE(VLOOKUP($E37,CODIFICACIÓN_DPA!$G$2:$H$3,2,FALSE),VLOOKUP($F37,CODIFICACIÓN_DPA!$J$2:$K$10,2,FALSE)),A37) -> 170175AV0208036 | D37: PIFO | E37: RURAL | F37: Valle de Tumbaco | G37: AVENTURA | H37: Laguna de Parcacocha | I37: La Laguna de Parcacocha, situada dentro del impresionante Parque Nacional Cayambe Coca, ofrece una experiencia única para los amantes de la naturaleza y la aventura. Este pintoresco lugar es perfecto para actividades al aire libre como el campismo, la pesca deportiva y emocionantes excursiones. Rodeada de majestuosas montañas y una exuberante vegetación, la Laguna de Parcacocha brinda un escenario tranquilo y sereno para disfrutar de la belleza natural de la región. Con su ambiente relajante y sus actividades emocionantes, esta laguna es un destino imperdible para aquellos que buscan conectarse con la naturaleza y explorar nuevas experiencias al aire libre. | J37: vía a Lago Agrio, el ingreso es por la Virgen de Papallacta | K37: -0.2957811 | L37: -78.179061 | M37: 1 hora de caminata | N37: Todos los dias 06h00 a 18h00 | O37: Gratuito | P37: Depende del grupo | Q37: No cazar No mascotas | R37: (02) 211-0370. (06) 232-9743
