Workbook

Sheet ESTRUCTURA CÓDIGO RUTA
A1: FICHA PARA EL LEVANTAMIENTO DE ATRACTIVOS TURÍSTICOS
A3: CÓDIGO DE LA RUTA TURÍSTICA
A5: El código, está compuesto por 09 dígitos (caracteres alfanuméricos), únicos e irrepetibles, mismo que aparecerá al inicio de la ficha para su identificación.
A7: 1. Clasificación de rutas turísticas (Nodo), (ver documento Centralidades - Nodos Turísticos Complementarios Urbanos y Rurales, 2024).
A8: 2. Se colocará la letra inicial de las dos primeras palabras que componen el nombre de la ruta ejemplo: Ruta Miradores codificación "RM"
A9: 3. Clasificación de rutas turísticas (Centralidad), (ver documento Centralidades - Nodos Turísticos Complementarios Urbanos y Rurales, 2024).
A10: 4. FInalmente; los tres dígitos finales corresponden al orden en que se levante la información de las rutas turísticas que iniciará desde 001.
A16: FUENTE: Manual Metodología para Jerarquización de Atractivos y Generación de Espacios Turísticos, MINTUR 2017.
A17: Centralidades - Nodos Turísticos Complementarios Urbanos y Rurales, QUITO TURISMO 2024.

Sheet CODIFICACIÓN_RUTA
B1: NODO_DESCRP | C1: COD_NODO | E1: CENTRALIDAD_DESCRIP | F1: COD_CENTRALIDAD | H1: ESTADO DEL ATRACTIVO
B2: URBANO | C2: 01 | E2: Centro Histórico | F2: 01 | H2: ACTIVO
B3: RURAL | C3: 02 | E3: La Mariscal | F3: 02 | H3: INACTIVO
E4: Centro Norte | F4: 03
E5: Parroquias Equinocciales | F5: 04
E6: Chocó Andino | F6: 05
E7: Ruta Escondida | F7: 06
E8: Valle de los Chillos | F8: 07
E9: Valle de Tumbaco | F9: 08
E10: Calderón | F10: 09
B17: CÓDIGO RUTA QT
B18: 01RM01002
B20: NODO | C20: NOMBRE DE LA RUTA TURÍSTICA | D20: CENTRALIDAD | E20: ORDEN EN LISTADO
B21: 01 | C21: RM | D21: 01 | E21: 002
B22: URBANO | C22: RUTA MIRADORES | D22: Centro Histórico | E22: 002

Sheet RUTAS
A1: N° | B1: ESTADO | C1: CÓDIGO QT | D1: NODO | E1: CENTRALIDAD | F1: NOMBRE DE LA RUTA TURÍSTICA | G1: CLASIFICACIÓN | H1: BREVE DESCRIPCIÓN | I1: MODALIDAD | J1: TIEMPO DE DURACIÓN DE RUTA (horas) | K1: DISTANCIA (Km) | L1: ALTITUD (m.s.n.m) | M1: DIFICULTAD | N1: LINK DE RUTA | O1: NOMBRE DEL ATRACTIVO / RECURSO ASOCIADO A LA RUTA 1 | P1: NOMBRE DEL ATRACTIVO / RECURSO ASOCIADO A LA RUTA 2 | Q1: NOMBRE DEL ATRACTIVO / RECURSO ASOCIADO A LA RUTA 3 | R1: NOMBRE DEL ATRACTIVO / RECURSO ASOCIADO A LA RUTA 4 | S1: NOMBRE DEL ATRACTIVO / RECURSO ASOCIADO A LA RUTA 5 | T1: NOMBRE DEL ATRACTIVO / RECURSO ASOCIADO A LA RUTA 6 | U1: NOMBRE DEL ATRACTIVO / RECURSO ASOCIADO A LA RUTA 7 | V1: NOMBRE DEL ATRACTIVO / RECURSO ASOCIADO A LA RUTA 8 | W1: NOMBRE DEL ATRACTIVO / RECURSO ASOCIADO A LA RUTA 9 | X1: NOMBRE DEL ATRACTIVO / RECURSO ASOCIADO A LA RUTA 10 | Y1: ESTABLECIMIENTO A&B | Z1: OBSERVACIÓN DE INACTIVACIÓN
A2: 001 | B2: ACTIVO | C2: =CONCATENATE(VLOOKUP($D2,CODIFICACIÓN_RUTA!$B$2:$C$3,2,0),MID($F2,1,1)&MID($F2,6,1),VLOOKUP($E2,CODIFICACIÓN_RUTA!$E$2:$F$10,2,0),$A2) -> 01RD01001 | D2: URBANO | E2: Centro Histórico | F2: RUTA DE LAS 7 CRUCES | G2: RUTAS CONSOLIDADAS | H2: Esta ruta se realiza en el Centro Histórico | I2: Cultural | J2: 1 | K2: 1.2 KM | L2: 2830 | M2: BAJA | N2: https://www.google.com/maps/d/u/0/edit?mid=1RjWO7kyHX4EsnPZu0Ll1cRFgkG4ECsI&usp=sharing | O2: Museo de la Ciudad | P2: Museo del Carmen Alto | Q2: Casa Museo María Augusta Urrutia | R2: Museo Numismático del Banco Central | S2: Iglesia Compañía de Jesús | T2: Centro Cultural Metropolitano | U2: Iglesia El Sagrario | V2: Catedral Metropolitana de Quito | W2: Iglesia Inmaculada Concepción
A3: 002 | B3: ACTIVO | C3: =CONCATENATE(VLOOKUP($D3,CODIFICACIÓN_RUTA!$B$2:$C$3,2,0),MID($F3,1,1)&MID($F3,6,1),VLOOKUP($E3,CODIFICACIÓN_RUTA!$E$2:$F$10,2,0),$A3) -> 01RM01002 | D3: URBANO | E3: Centro Histórico | F3: RUTA MIRADORES | G3: RUTAS CON POTENCIAL | H3: Se podrá disfrutar de los distintos miradores que posee la ciudad de Quito, junto con Quito Tour Bus | I3: Natural | J3: 5 | K3: 17 KM | L3: 3100 | M3: BAJA | N3: https://www.google.com/maps/d/edit?mid=1upWwdyGKcSFM8yEOjftREmBG9ap95MI&usp=sharing | O3: Basílica del Voto Nacional | P3: Museo del agua YAKU | Q3: Centro Cultural Itchimbía | R3: Museo Templo de la Patria | S3: Monumento Virgen de El Panecillo
A4: 003 | B4: ACTIVO | C4: =CONCATENATE(VLOOKUP($D4,CODIFICACIÓN_RUTA!$B$2:$C$3,2,0),MID($F4,1,1)&MID($F4,6,1),VLOOKUP($E4,CODIFICACIÓN_RUTA!$E$2:$F$10,2,0),$A4) -> 01RA03003 | D4: URBANO | E4: CENTRO NORTE | F4: RUTA ARQUEOLÓGICA | G4: RUTAS CON POTENCIAL | H4: Conocer sobre las culturas y habitantes antiguos de Quito. | I4: Histórica | J4: 5 | K4: 23 KM | L4: 2800 | M4: BAJA | N4: https://www.google.com/maps/d/edit?mid=1UIGgFhBe6Z3u0nI8BmeggIxUUrbLpbQ&usp=drive_link | O4: Museo de Sitio La Florida | P4: Parque Arqueológico y Ecológico Rumipamba | Y4: SANTHORNO
A5: 004 | B5: ACTIVO | C5: =CONCATENATE(VLOOKUP($D5,CODIFICACIÓN_RUTA!$B$2:$C$3,2,0),MID($F5,1,1)&MID($F5,6,1),VLOOKUP($E5,CODIFICACIÓN_RUTA!$E$2:$F$10,2,0),$A5) -> 01RD02004 | D5: URBANO | E5: La Mariscal | F5: RUTA DE LA PALABRA | G5: RUTAS CON POTENCIAL | H5: Nos permite conocer la Plaza de los Presidentes, la Iglesia de Santa Teresita, la Casa de Camilo Ponce Enríquez, el palacete González Artigas, el Centro Cultural Benjamín Carrión, el Patio de Comedias y el espacio sociocultural Buenaventura. | I5: Cultural | J5: 3 | K5: 1.5 KM | L5: 2850 | M5: BAJA | N5: https://www.google.com/maps/d/edit?mid=11FnWDoB3rJsva7gtAKabLoeJWKLEJpI&usp=drive_link | O5: Iglesia de Santa Teresita | P5: Centro Cultural Benjamín Carrión | Q5: Museo MUNA Ecuador
A6: 005 | B6: ACTIVO | C6: =CONCATENATE(VLOOKUP($D6,CODIFICACIÓN_RUTA!$B$2:$C$3,2,0),MID($F6,1,1)&MID($F6,6,1),VLOOKUP($E6,CODIFICACIÓN_RUTA!$E$2:$F$10,2,0),$A6) -> 01RC01005 | D6: URBANO | E6: Centro Histórico | F6: RUTA CHOCOLATE ENTRE CÚPULAS Y TORRES | G6: RUTAS CONSOLIDADAS | H6: Se podran disfrutar de las cúpulas de la Basílica del Voto Nacional y la Iglesia de La Compañia además de una cata de chocolate fino. | I6: Gastronómica | J6: 4 | K6: 1 KM | L6: 2820 | M6: BAJA | N6: https://www.google.com/maps/d/edit?mid=18vd0Hx6XK01LFkorLhnokI_vDp3EeM0&usp=drive_link | O6: Basílica del Voto Nacional | P6: Iglesia Compañía de Jesús | Q6: Catedral Metropolitana de Quito | Y6: CHOCOLATE CHEZ TIFF
A7: 006 | B7: ACTIVO | C7: =CONCATENATE(VLOOKUP($D7,CODIFICACIÓN_RUTA!$B$2:$C$3,2,0),MID($F7,1,1)&MID($F7,6,1),VLOOKUP($E7,CODIFICACIÓN_RUTA!$E$2:$F$10,2,0),$A7) -> 01RR01006 | D7: URBANO | E7: Centro Histórico | F7: RUTA ROMANCE Y LIBERTADORES | G7: RUTAS CON POTENCIAL | H7: Disfrutaremos de mano de los libertadores las historias de amores,política del Quito revolucionario. | I7: Cultural | J7: 3 | K7: 0.77 KM | L7: 2850 | M7: BAJA | N7: https://www.google.com/maps/d/edit?mid=1BmEgyZffuOaFNfpA9kjukiV5BAmn6aY&usp=drive_link | O7: Convento de San Francisco | P7: Iglesia Compañía de Jesús | Q7: Centro Cultural Metropolitano | R7: Catedral Metropolitana de Quito | Y7: HELADERIA DE SAN AGUSTIN
A8: 007 | B8: ACTIVO | C8: =CONCATENATE(VLOOKUP($D8,CODIFICACIÓN_RUTA!$B$2:$C$3,2,0),MID($F8,1,1)&MID($F8,6,1),VLOOKUP($E8,CODIFICACIÓN_RUTA!$E$2:$F$10,2,0),$A8) -> 01RD01007 | D8: URBANO | E8: Centro Histórico | F8: RUTA DE OFICIOS Y PERSONAJES QUITEÑOS | G8: RUTAS POR FORTALECER | H8: Conocermos sobre los nobles oficios que todavián prevalecen en la ciudad capitalina. | I8: Histórica | J8: 4 | K8: 2.7 KM | L8: 2825 | M8: BAJA | N8: https://www.google.com/maps/d/edit?mid=1gfoDaWH4tRywZ4FAAwdlp2C5sJAAxi0&usp=sharing | O8: Museo Casa Manuela Sáenz | P8: Museo Fray Pedro Bedón | Y8: CASA 925
A9: 008 | B9: ACTIVO | C9: =CONCATENATE(VLOOKUP($D9,CODIFICACIÓN_RUTA!$B$2:$C$3,2,0),MID($F9,1,1)&MID($F9,6,1),VLOOKUP($E9,CODIFICACIÓN_RUTA!$E$2:$F$10,2,0),$A9) -> 01RC01008 | D9: URBANO | E9: Centro Histórico | F9: RUTA CÚPULAS Y TORRES | G9: RUTAS CONSOLIDADAS | H9: Se podran disfrutar de las cúpulas de la Basílica del Voto Nacional y la Iglesia de La Compañia además de una cata de chocolate fino. | I9: Cultural | J9: 4 | K9: 1.6 KM | L9: 2850 | M9: BAJA | N9: https://www.google.com/maps/d/edit?mid=1m291Fej0LC17aa9Mrk7SeyOr76wGXe0&usp=sharing | O9: Basílica del Voto Nacional | P9: Catedral Metropolitana de Quito | Q9: Museo Fray Pedro Bedón | Y9: CASA925
A10: 009 | B10: ACTIVO | C10: =CONCATENATE(VLOOKUP($D10,CODIFICACIÓN_RUTA!$B$2:$C$3,2,0),MID($F10,1,1)&MID($F10,6,1),VLOOKUP($E10,CODIFICACIÓN_RUTA!$E$2:$F$10,2,0),$A10) -> 01RP01009 | D10: URBANO | E10: Centro Histórico | F10: RUTA PLAZAS Y MONUMENTOS | G10: RUTAS POR FORTALECER | H10: Visitaremos y aprenderemos sobre las plazas y monumentos que habitan en el Centro Histórico. (Plaza del Teatro- Plaza Huerto San Agustín - Plaza de la Independencia – Plazoleta Gonzáles Suárez - Plaza Santa Domingo – Plaza Santa Clara- Plaza San Francisco) | I10: Cultural | J10: 4 | K10: 2.4 KM | L10: 2830 | M10: BAJA | N10: https://www.google.com/maps/d/edit?mid=1zcXCzE4agYintmlQhUJoTZ62eKDYP14&usp=sharing | O10: Convento de San Agustín | P10: Teatro Sucre | Q10: Catedral Metropolitana de Quito | R10: Convento de Santo Domingo | S10: Iglesia de Santa Clara | T10: Convento de San Francisco
A11: 010 | B11: ACTIVO | C11: =CONCATENATE(VLOOKUP($D11,CODIFICACIÓN_RUTA!$B$2:$C$3,2,0),MID($F11,1,1)&MID($F11,6,1),VLOOKUP($E11,CODIFICACIÓN_RUTA!$E$2:$F$10,2,0),$A11) -> 01SA01010 | D11: URBANO | E11: Centro Histórico | F11: SAN MARCOS – ARTE PATRIMONIO Y CULTURA | G11: RUTAS CON POTENCIAL | H11: Disfrutaremos de este barrio emblématico de Quito y conoceremos el arte que habita en él. | I11: Cultural | J11: 4 | K11: 2.4 KM | L11: 2830 | M11: BAJA | N11: https://www.google.com/maps/d/edit?mid=13MkAa7jCO5tg1sZbr4478dbRaWSGyHc&usp=sharing | O11: Museo Casa Manuela Sáenz | P11: Museo Muñoz Mariño | Q11: Museo de Arquitectura | R11: Iglesia de San Marcos
A12: 011 | B12: ACTIVO | C12: =CONCATENATE(VLOOKUP($D12,CODIFICACIÓN_RUTA!$B$2:$C$3,2,0),MID($F12,1,1)&MID($F12,6,1),VLOOKUP($E12,CODIFICACIÓN_RUTA!$E$2:$F$10,2,0),$A12) -> 01RC01011 | D12: URBANO | E12: Centro Histórico | F12: RUTA CITY TOUR CIUDAD DE QUITO | G12: RUTAS CON POTENCIAL | H12: Contemplaremos nuestra carita de Dios, mientras aprendemos sobre sus monumentos, historias, tradiciones. | I12: Cultural | J12: 4 | K12: 1.25 KM | L12: 2850 | M12: BAJA | N12: https://www.google.com/maps/d/edit?mid=11MgTI4xtbGHxjnoLXYtJbs9e9OdW_QQ&usp=sharing | O12: Catedral Metropolitana de Quito | P12: Centro Cultural Metropolitano | Q12: Iglesia Compañía de Jesús | R12: Convento de San Francisco | S12: Monumento Virgen de El Panecillo | Y12: Casa 925
A13: 012 | B13: ACTIVO | C13: =CONCATENATE(VLOOKUP($D13,CODIFICACIÓN_RUTA!$B$2:$C$3,2,0),MID($F13,1,1)&MID($F13,6,1),VLOOKUP($E13,CODIFICACIÓN_RUTA!$E$2:$F$10,2,0),$A13) -> 02RE04012 | D13: RURAL | E13: Parroquias Equinocciales | F13: RUTA EQUINOCCIAL ANCESTRAL Y CULTURAL | G13: RUTAS CONSOLIDADAS | H13: El objetivo de esta ruta es vincular propuestas culturales de la Parroquias rurales de Pomasqui, San Antonio de Pichincha y Calacalí. | I13: Histórica | J13: 9 | K13: 16.5 KM | L13: 2800 | M13: BAJA | N13: https://www.google.com/maps/d/u/0/edit?mid=1hLFaHdE51z9g8iAhOcMvKGespI-utM8&usp=sharing | O13: Chucchurillos Ñaupa Ayllu Manta | P13: Puracá de Rumicucho | Q13: Casa Museo Carlota Jaramillo | Y13: EL PATIO ORGANIC TRADICIONAL FOOD
A14: 013 | B14: ACTIVO | C14: =CONCATENATE(VLOOKUP($D14,CODIFICACIÓN_RUTA!$B$2:$C$3,2,0),MID($F14,1,1)&MID($F14,6,1),VLOOKUP($E14,CODIFICACIÓN_RUTA!$E$2:$F$10,2,0),$A14) -> 02RC07013 | D14: RURAL | E14: VALLE DE LOS CHILLOS | F14: RUTA CHAKANA - EN BUSCA DEL CÓNDOR ANDINO Y EL OSO DE ANTEOJOS | G14: RUTAS CONSOLIDADAS | H14: El objetivo de esta ruta es poder conocer distintos lugares y sus miradoes donde se puede avistar al cóndor andino, venados de cola blanca y oso de anteojos. | I14: CAVE | J14: 10 | K14: 46 KM | L14: 2830 | M14: BAJA | N14: https://www.google.com/maps/d/edit?mid=1WfFDmpjbXAMjNtlV6xomg4tkf6LlDDQ&usp=drive_link | O14: Chakana - Antisanilla Peñón del Isco | P14: Laguna de Secas | Y14: Chakana Tambo Cóndor
A15: 014 | B15: ACTIVO | C15: =CONCATENATE(VLOOKUP($D15,CODIFICACIÓN_RUTA!$B$2:$C$3,2,0),MID($F15,1,1)&MID($F15,6,1),VLOOKUP($E15,CODIFICACIÓN_RUTA!$E$2:$F$10,2,0),$A15) -> 02RE05014 | D15: RURAL | E15: CHOCÓ ANDINO | F15: RUTA EN BUSCA DEL JARDÍN DE COLIBRÍES + GASTRONOMÍA LOCAL (YANACOCHA) | G15: RUTAS CONSOLIDADAS | H15: Es un recorrido donde se podran avistar aves como tangaras y gralarias, se conocera el bosque nublado donde se puede disfrutar del canto de las aves. | I15: CAVE | J15: 7 | K15: 46 KM | L15: 2830 | M15: BAJA | N15: https://www.google.com/maps/d/edit?mid=1yS4As1P4RYZBvsSt5_CfKH8_vd1IABs&usp=drive_link | O15: Yanacocha
A16: 015 | B16: ACTIVO | C16: =CONCATENATE(VLOOKUP($D16,CODIFICACIÓN_RUTA!$B$2:$C$3,2,0),MID($F16,1,1)&MID($F16,6,1),VLOOKUP($E16,CODIFICACIÓN_RUTA!$E$2:$F$10,2,0),$A16) -> 02RE06015 | D16: RURAL | E16: RUTA ESCONDIDA | F16: RUTA ESCONDIDA PUÉLLARO Y PERUCHO PUÉLLARO – PERUCHO | G16: RUTAS CONSOLIDADAS | H16: Se podrá disfrutar de las maravillas escondidas dentro de la Ruta Escondida, su historia, cultura y arquitectura. | I16: Cultural | J16: 8 | K16: 70 KM | L16: 2850 | M16: BAJA | N16: https://www.google.com/maps/d/edit?mid=1CHPVBnxTtTGfGbt5HSeKJizmcw-P6Dc&usp=drive_link | O16: Iglesia de Puéllaro | P16: Cerro La Luz | Q16: Iglesia de Perucho | R16: Museo del Aguacate
A17: 016 | B17: ACTIVO | C17: =CONCATENATE(VLOOKUP($D17,CODIFICACIÓN_RUTA!$B$2:$C$3,2,0),MID($F17,1,1)&MID($F17,6,1),VLOOKUP($E17,CODIFICACIÓN_RUTA!$E$2:$F$10,2,0),$A17) -> 02RM05016 | D17: RURAL | E17: CHOCÓ ANDINO | F17: RUTA MUSEO DE TULIPE – FINCA RUMISITANA | G17: RUTAS POR FORTALECER | H17: El Museo de sitio funciona en los vestigios de un centro ceremonial de los yumbos, en este lugar se puede encontrar estructuras hundidas con muros de piedra relacionadas al agua. Se realizará el “Tour del café con leche” caminata corta a los cultivos de café de altura, el proceso de secado y campos de producción lechera. Se degustará café y como obsequio una bolsa de café producido en la finca. | I17: CAVE | J17: 7 | K17: 101 KM | L17: 1400 | M17: BAJA | N17: https://www.google.com/maps/d/edit?mid=1EJ_ZcmLL5V_YxyTR-DR0v3voFkFu2II&usp=drive_link | O17: Museo de Sitio Tulipe | Y17: FINCA RUMISTINA
A18: 017 | B18: ACTIVO | C18: =CONCATENATE(VLOOKUP($D18,CODIFICACIÓN_RUTA!$B$2:$C$3,2,0),MID($F18,1,1)&MID($F18,6,1),VLOOKUP($E18,CODIFICACIÓN_RUTA!$E$2:$F$10,2,0),$A18) -> 02RD09017 | D18: RURAL | E18: Calderón | F18: RUTA DE LOS BORDADOS Y HUERTOS | G18: RUTAS CONSOLIDADAS | H18: Visitaremos diversos huertos de Llano Grande para conocer sobre las tradiciones del pueblo Kitu Kara. | I18: Cultural | J18: 8 | K18: 70 KM | L18: 2850 | M18: BAJA | N18: https://www.google.com/maps/d/edit?mid=1xECrXgFMf3CJLAbbk8RgNNh1g3wbLn8&usp=drive_link | O18: Mindalae | P18: Museo Capilla del Hombre | Q18: Parque Metropolitano Guanguilagua
A19: 018 | B19: ACTIVO | C19: =CONCATENATE(VLOOKUP($D19,CODIFICACIÓN_RUTA!$B$2:$C$3,2,0),MID($F19,1,1)&MID($F19,6,1),VLOOKUP($E19,CODIFICACIÓN_RUTA!$E$2:$F$10,2,0),$A19) -> 02RD04018 | D19: RURAL | E19: PARROQUIAS EQUINOCCIALES | F19: RUTA DESCUBRIENDO EL CENTRO DEL MUNDO | G19: RUTAS CON POTENCIAL | H19: Se puede disfrutar de un recorrido a Calacalí, Museo Carlota Jaramillo, Museo del Intiñan y Casa Agave | I19: Cultural | J19: 6 | K19: 46 KM | L19: 2830 | M19: BAJA | N19: https://www.google.com/maps/d/edit?mid=1JwEH-1fjjFncTMoXKZ9n4RPqfkNPsoY&usp=drive_link | O19: Museo Capilla del Hombre | P19: Museo Templo del Sol | Q19: Museo Intiñan | R19: Casa Agave | S19: Casa Museo Carlota Jaramillo
A20: 019 | B20: ACTIVO | C20: =CONCATENATE(VLOOKUP($D20,CODIFICACIÓN_RUTA!$B$2:$C$3,2,0),MID($F20,1,1)&MID($F20,6,1),VLOOKUP($E20,CODIFICACIÓN_RUTA!$E$2:$F$10,2,0),$A20) -> 02RC04019 | D20: RURAL | E20: PARROQUIAS EQUINOCCIALES | F20: RUTA CENTRO DEL MUNDO | G20: RUTAS CON POTENCIAL | H20: Podremos visitar uno de los templos dedicados al arte y vivir la experiencia de los saberes ancestrales, además de visitar el magestuoso Pululahua y el museo Carlota Jaramillo. | I20: Cultural | J20: 8 | K20: 46 KM | L20: 2830 | M20: BAJA | N20: https://www.google.com/maps/d/edit?mid=1Pc4frukcLLeckLXfd1NipMh4jSDbgTQ&usp=drive_link | O20: Reserva Geobotánica Pululahua | P20: MUSEO TEMPLO DEL SOL | Q20: MUSEO CARLOTA JARAMILLO
A21: 020 | B21: ACTIVO | C21: =CONCATENATE(VLOOKUP($D21,CODIFICACIÓN_RUTA!$B$2:$C$3,2,0),MID($F21,1,1)&MID($F21,6,1),VLOOKUP($E21,CODIFICACIÓN_RUTA!$E$2:$F$10,2,0),$A21) -> 02RC04020 | D21: RURAL | E21: PARROQUIAS EQUINOCCIALES | F21: RUTA CENTRO DEL MUNDO CON EL QUITO TOUR BUS | G21: RUTAS CON POTENCIAL | H21: Podremos visitar la Ciudad Mitad del Mundo y además apreciar el magestuoso Pululahua. | I21: Cultural | J21: 8 | K21: 40 KM | L21: 2800 | M21: BAJA | N21: https://www.google.com/maps/d/viewer?mid=1YAiHbP_szS9lt85Q0ZmVgnBw-uCjr5w&ll=-0.01814251929989333%2C-78.46965506884766&z=13 | O21: Galería Kingman | P21: Alianza Francesa | Q21: Museo Capilla del Hombre | R21: Museo Templo del Sol | S21: RESERVA GEOBOTÁNICA PULULAHUA | Y21: CERVECERÍA SANTA ANA
A22: 021 | B22: ACTIVO | C22: =CONCATENATE(VLOOKUP($D22,CODIFICACIÓN_RUTA!$B$2:$C$3,2,0),MID($F22,1,1)&MID($F22,6,1),VLOOKUP($E22,CODIFICACIÓN_RUTA!$E$2:$F$10,2,0),$A22) -> 02RC04021 | D22: RURAL | E22: Parroquias Equinocciales | F22: RUTA CULUNCO YUNGUILLA | G22: RUTAS POR FORTALECER | H22: Visitaremos la Comunidad e Yunguilla y su ejeompo de Turismo Comunitario, disfrutaremos de una maravillosas caminira donde podremos conocer los caminos pre-incaicos de la cultura Yumbo. | I22: Natural | J22: 7 | K22: 100 KM | L22: 3100 | M22: MEDIA | N22: https://www.google.com/maps/d/edit?mid=1tzpaRD6f6ZlpsAwRWhvkG9oZImX6nqA&usp=drive_link | O22: Museo Templo del Sol | P22: Museo Intiñan | Q22: Casa Museo Carlota Jaramillo | R22: Comunidad de Yunguilla | S22: Culunco Guantopungo
A23: 022 | B23: ACTIVO | C23: =CONCATENATE(VLOOKUP($D23,CODIFICACIÓN_RUTA!$B$2:$C$3,2,0),MID($F23,1,1)&MID($F23,6,1),VLOOKUP($E23,CODIFICACIÓN_RUTA!$E$2:$F$10,2,0),$A23) -> 02RH08022 | D23: RURAL | E23: Valle de Tumbaco | F23: RUTA HISTORIA, FAUNA Y GASTRONOMÍA EL QUINCHE - GUAYLLABAMBA | G23: RUTAS CON POTENCIAL | H23: Podremos disfrutar de esta ruta donde visitaremos el Santuario del Quinche y sus cúpulas, el zoológico de Guayllabamba y la fauna que habita en el. | I23: Cultural | J23: 8 | K23: 50 KM | L23: 2850 | M23: BAJA | N23: https://www.google.com/maps/d/edit?mid=1VDavNZhOfRds6GiNyo--oSyh9VzGP2g&usp=drive_link | O23: Santuario de Nuestra Señora del Quinche | P23: Zoológico de Guayllabamba
A24: 023 | B24: ACTIVO | C24: =CONCATENATE(VLOOKUP($D24,CODIFICACIÓN_RUTA!$B$2:$C$3,2,0),MID($F24,1,1)&MID($F24,6,1),VLOOKUP($E24,CODIFICACIÓN_RUTA!$E$2:$F$10,2,0),$A24) -> 02RM05023 | D24: RURAL | E24: Chocó Andino | F24: RUTA MAQUIPUCUNA | G24: RUTAS POR FORTALECER | H24: Disfrutaremos de esta maravillosa Reserva donde caminaremos por sus diversos senderos y avistaremos fauna endémica del lugar, más su deliciosa gastronomía. | I24: CAVE | J24: 7 | K24: 100 KM | L24: 3100 | M24: MEDIA | N24: https://www.google.com/maps/d/edit?mid=1-CFiq0E6k5sMmjOj7_7qeTo61CAMFCc&usp=drive_link | O24: Casa Museo Carlota Jaramillo | P24: Reserva Orquideologica Pahuma | Q24: Reserva Maquipucuna
A25: 024 | B25: ACTIVO | C25: =CONCATENATE(VLOOKUP($D25,CODIFICACIÓN_RUTA!$B$2:$C$3,2,0),MID($F25,1,1)&MID($F25,6,1),VLOOKUP($E25,CODIFICACIÓN_RUTA!$E$2:$F$10,2,0),$A25) -> 01RM01024 | D25: URBANO | E25: Centro Histórico | F25: RUTA MÚSICA, HISTORIA, TRADICIÓN Y ARTESANOS. | G25: RUTAS CON POTENCIAL | H25: El objetivo de esta ruta es conocer sobre las historias de las calles del Quito Colonial, visitaremos el Museo de la Ciudad y degustaremos de la gastronomía Quiteña en la famosa calle La Ronda | I25: Cultural | J25: 4 | K25: 1 KM | L25: 2830 | M25: BAJA | N25: https://www.google.com/maps/d/edit?mid=1H4_hh0ulWv-1xk4dTlmYvKj3FRMn_as&usp=drive_link | O25: Catedral Metropolitana de Quito | P25: Museo de la Ciudad | Y25: Casa 925
A26: 025 | B26: ACTIVO | C26: =CONCATENATE(VLOOKUP($D26,CODIFICACIÓN_RUTA!$B$2:$C$3,2,0),MID($F26,1,1)&MID($F26,6,1),VLOOKUP($E26,CODIFICACIÓN_RUTA!$E$2:$F$10,2,0),$A26) -> 02RP08025 | D26: RURAL | E26: Valle de Tumbaco | F26: RUTA PIFO,CULTURA, NATURALEZA Y TRADICIÓN | G26: RUTAS POR FORTALECER | H26: Conoceremos sobre la historia de este maravillos lugar, visitaremos la Hacienda Ecuestre Chantag, su Iglesia entre otros espacios. | I26: Cultural | J26: 6 | K26: 70 KM | L26: 2850 | M26: BAJA | N26: https://www.google.com/maps/d/edit?mid=1yWOw43xtH4FbNqo9xCSThqvD2WOaDkA&usp=drive_link | Y26: Hacienda Ecuestre Chantag
A27: 026 | B27: ACTIVO | C27: =CONCATENATE(VLOOKUP($D27,CODIFICACIÓN_RUTA!$B$2:$C$3,2,0),MID($F27,1,1)&MID($F27,6,1),VLOOKUP($E27,CODIFICACIÓN_RUTA!$E$2:$F$10,2,0),$A27) -> 01RT01026 | D27: URBANO | E27: Centro Histórico | F27: RUTA TRADICIONES Y LEGADO FRANCISCANO | G27: RUTAS CON POTENCIAL | H27: Visitaremos uno de los mercados más antiguios de la ciudad quiteña y de la mano de las hierbateras conocermos sobre los saberes ancestrales y uso de plantas medicinales , degustación de dulces tradicionales y una visita dentro del convento más grande de latinoamerica. | I27: Cultural | J27: 3 | K27: 0.7 KM | L27: 2850 | M27: BAJA | N27: https://www.google.com/maps/d/edit?mid=1wDE7ScASCtjFylIgEV7crp_HLIPp4Mk&usp=drive_link | O27: Mercado de San Francisco | P27: Convento de San Francisco
A28: 027 | B28: INACTIVO | C28: =CONCATENATE(VLOOKUP($D28,CODIFICACIÓN_RUTA!$B$2:$C$3,2,0),MID($F28,1,1)&MID($F28,6,1),VLOOKUP($E28,CODIFICACIÓN_RUTA!$E$2:$F$10,2,0),$A28) -> 02RG08027 | D28: RURAL | E28: Valle de Tumbaco | F28: RUTA GASTRONÓMICA | G28: RUTAS CON POTENCIAL | H28: El objetivo de esta ruta es poder degustar y vivir de una manera innovadora la gastronomía del DMQ. | I28: Gastronómica | J28: 7 | L28: 2600 | M28: BAJA | N28: https://www.google.com/maps/d/viewer?mid=1f5eVi_Jy8pNHTR0P9R547e9Q5muBQa0&ll=-0.2003635849838867%2C-78.34611313492223&z=12 | O28: Iglesia de Santa Teresita | P28: Parque Metropolitano Guanguilagua | Q28: Santuario de Nuestra Señora del Quinche | Z28: Es circuito (No operativo)
A29: 028 | B29: ACTIVO | C29: =CONCATENATE(VLOOKUP($D29,CODIFICACIÓN_RUTA!$B$2:$C$3,2,0),MID($F29,1,1)&MID($F29,6,1),VLOOKUP($E29,CODIFICACIÓN_RUTA!$E$2:$F$10,2,0),$A29) -> 01RH02028 | D29: URBANO | E29: La Mariscal | F29: RUTA HISTORIA Y CULTURA EN LA MARISCAL | G29: RUTAS CONSOLIDADAS | H29: Nos sumergiremos en la historia de este barrio que mezcla da modernidad con la arquitectura del siglo XX, recorreremos monumentos como el Arco de la Circasiana, disfrutaremos de la calidad y variedad de productos que ese encuentran el Mercado artesanal, hablaremos de Benjamin Carrión y su hogar que ahora forma el Centro Cultural con su mismo nombre y conoceremos sobre la vida religiosa del barrio en la Iglesia de Santa Teresita. | I29: Cultural | J29: 4 | K29: 1 KM | L29: 2830 | M29: BAJA | N29: https://www.google.com/maps/d/u/0/edit?mid=1sTpy2NuchI3ofXDPfLloqyoMdtIAVhE&usp=sharing | O29: Arco de la Circasiana | P29: Mercado Artesanal | Q29: Centro Cultural Benjamín Carrión | R29: Iglesia de Santa Teresita
A30: 029 | B30: ACTIVO | C30: =CONCATENATE(VLOOKUP($D30,CODIFICACIÓN_RUTA!$B$2:$C$3,2,0),MID($F30,1,1)&MID($F30,6,1),VLOOKUP($E30,CODIFICACIÓN_RUTA!$E$2:$F$10,2,0),$A30) -> 02RL05029 | D30: RURAL | E30: Chocó Andino | F30: RUTA LAS PUERTAS DEL CHOCÓ ANDINO | G30: RUTAS CONSOLIDADAS | H30: Visitaremos esl sitio arqueológico Rumicucho. Recorreremos el templo del sol y la luna, descubriremos obras de arte del maestro Cristóbal Ortega, dentro de la Reserva Geobotánica Pululahua visitaremos el Mirador Ventanillas, degustaremos de exquisito al muerzo en la "Cuchara orgánica", y recorreremos el centro de Calacalí | I30: Cultural | J30: 6 | K30: 2.72 KM | L30: 1400 | M30: BAJA | N30: https://www.google.com/maps/d/u/0/edit?mid=1ehyfYRvJ4ehSjTKcX9GjcgU-TsqyzI0&usp=sharing | O30: Puracá de Rumicucho | P30: Museo Templo del Sol Pintor Cristobal Orteaga | Q30: Reserva Geobotánica Pululahua | R30: Monumento a la Mitad del Mundo - Calacalí | S30: Casa Museo Carlota Jaramillo
A31: 030 | B31: ACTIVO | C31: =CONCATENATE(VLOOKUP($D31,CODIFICACIÓN_RUTA!$B$2:$C$3,2,0),MID($F31,1,1)&MID($F31,6,1),VLOOKUP($E31,CODIFICACIÓN_RUTA!$E$2:$F$10,2,0),$A31) -> 02RC08030 | D31: RURAL | E31: Valle de Tumbaco | F31: RUTA CHAQUIÑAN - CUMBAYA | G31: RUTAS CON POTENCIAL | H31: Disfrutaremos de uno de los parque más grandes de Quito , conoceremos uno de los antiguos tramos del ferrocaril, podremos aprender sobre la historia de Cumbaya en su Iglesia. | I31: Cultural | J31: 6 | K31: 2.72 KM | L31: 2420 | M31: MEDIA | N31: https://www.google.com/maps/d/u/0/edit?mid=1vuSoWg_3Qfxs68PSgRuS4YE6EpCt8_U&usp=sharing | O31: Parque Ecológico Los Algarrobos | P31: Ruta Ecológica El Chaquiñán de Cumbaya | Q31: Iglesia San Pedro de Cumbayá
A32: 031 | B32: ACTIVO | C32: =CONCATENATE(VLOOKUP($D32,CODIFICACIÓN_RUTA!$B$2:$C$3,2,0),MID($F32,1,1)&MID($F32,6,1),VLOOKUP($E32,CODIFICACIÓN_RUTA!$E$2:$F$10,2,0),$A32) -> 01RU01031 | D32: URBANO | E32: Centro Histórico | F32: RUTA UN DÍA DE GUAGUAS | G32: RUTAS CON POTENCIAL | H32: MEDIA | I32: Cultural | J32: 5 | K32: 2.24 KM | L32: 2850 | M32: BAJA | N32: https://www.google.com/maps/d/u/0/edit?mid=1vuSoWg_3Qfxs68PSgRuS4YE6EpCt8_U&usp=sharing | O32: Museo Templo de la Patria | P32: Museo Interactivo de Ciencias | Y32: Casa 925
A33: 032 | B33: ACTIVO | C33: =CONCATENATE(VLOOKUP($D33,CODIFICACIÓN_RUTA!$B$2:$C$3,2,0),MID($F33,1,1)&MID($F33,6,1),VLOOKUP($E33,CODIFICACIÓN_RUTA!$E$2:$F$10,2,0),$A33) -> 02RP08032 | D33: RURAL | E33: Valle de Tumbaco | F33: RUTA PIFO: NATURALEZA Y DIVERSIÓN EN FAMILIA | G33: RUTAS CONSOLIDADAS | H33: Disfrutaremos de un día lleno de experiencias relacionadas con el medio ambiente en Atukpamba Mulauco además de recorrer Escorza granja orgánica, em la Granja Inga podremos visitar a las avestruces e interactuaremos con los animales de la granja. | I33: Cultural | J33: 8 | K33: 22.6 KM | L33: 2770 | M33: BAJA | N33: https://www.google.com/maps/d/u/0/edit?mid=17CtkarX0KqwP73BOMqyOm39RM3XJPak&usp=sharing | Y33: Atukpamba Mulauco Escorza granja órganica Itulcachi Granja Inga
A34: 033 | B34: ACTIVO | C34: =CONCATENATE(VLOOKUP($D34,CODIFICACIÓN_RUTA!$B$2:$C$3,2,0),MID($F34,1,1)&MID($F34,6,1),VLOOKUP($E34,CODIFICACIÓN_RUTA!$E$2:$F$10,2,0),$A34) -> 01RP01033 | D34: URBANO | E34: Centro Histórico | F34: RUTA PARQUES NOCTURNA | G34: RUTAS CON POTENCIAL | H34: Conoceremos sobre el emblemático Parque iItchimbia junto con personajes de leyenda, además de visitar la Hacienda de Piedrahita cuya historia trae recuerdos de la primera estación comercial de TV | I34: Cultural | J34: 2.3 | K34: 1.3 KM | L34: 2910 | M34: BAJA | N34: https://www.google.com/maps/d/u/0/edit?mid=10qtml-aGHZtUslN2XTfvIxABsZOiCjo&usp=sharing | O34: Centro Cultural Itchimbía
A35: 034 | B35: ACTIVO | C35: =CONCATENATE(VLOOKUP($D35,CODIFICACIÓN_RUTA!$B$2:$C$3,2,0),MID($F35,1,1)&MID($F35,6,1),VLOOKUP($E35,CODIFICACIÓN_RUTA!$E$2:$F$10,2,0),$A35) -> 01RB01034 | D35: URBANO | E35: Centro Histórico | F35: RUTA BARRIOS TRADICIONALES (SAN BLAS) | G35: RUTAS CON POTENCIAL | H35: Visitaremos el templo más antiguo de Quito, conoceremos astronomía en el observatorio, conoceremos sobre el monumento a Simón Bolívar, Círculo Militar la Filantrópica, Iglesia de San Blas, entre otros lugares. | I35: Cultural | J35: 3 | K35: 2.4 KM | L35: 2230 | M35: BAJA | N35: https://www.google.com/maps/d/u/0/edit?mid=1TRYg5TbzKkeQD-_7KT97aGa-6tn9HaU&usp=sharing | O35: Iglesia El Belén | P35: Museo del Observatorio Astronómico de Quito | Q35: Iglesia de San Blas | Y35: Plaza Belmonte
A36: 035 | B36: ACTIVO | C36: =CONCATENATE(VLOOKUP($D36,CODIFICACIÓN_RUTA!$B$2:$C$3,2,0),MID($F36,1,1)&MID($F36,6,1),VLOOKUP($E36,CODIFICACIÓN_RUTA!$E$2:$F$10,2,0),$A36) -> 01RB01035 | D36: URBANO | E36: Centro Histórico | F36: RUTA BARRIOS TRADICIONALES (LA TOLA) | G36: RUTAS CON POTENCIAL | H36: Hablaremos de la historia de este barrio colonial, sus tradiciones y leyendas además de disfrutar de demostraciones de arte. | I36: Cultural | J36: 3 | K36: 2.3 KM | L36: 2910 | M36: BAJA | N36: https://www.google.com/maps/d/u/0/edit?mid=1sAJh2cq3jTUGW7scwVvUD97CMgPaIns&usp=sharing | O36: Centro Cultural Itchimbía
A37: 036 | B37: ACTIVO | C37: =CONCATENATE(VLOOKUP($D37,CODIFICACIÓN_RUTA!$B$2:$C$3,2,0),MID($F37,1,1)&MID($F37,6,1),VLOOKUP($E37,CODIFICACIÓN_RUTA!$E$2:$F$10,2,0),$A37) -> 02RL07036 | D37: RURAL | E37: Valle de los Chillos | F37: RUTA LAGUNA DE SECAS - PINTAG | G37: RUTAS CONSOLIDADAS | H37: Visitaremos el Parque Central de Pintag, y podremos realizar caminatas alrededor de diversas lagunas como: Micacocha, laguna de secas,visitaremos el Peñon del Isco y degustaremos de un almuerzo típico de la zona | I37: Natural | J37: 7 | K37: 50 KM | L37: 3460 | M37: MEDIA | N37: https://www.google.com/maps/d/u/0/edit?mid=131L5esv4Jicj3Ntl8cAptNDtARjxYc0&usp=sharing | O37: Volcán Antisana | P37: Peñon del Isco | Q37: Laguna de Secas | R37: Laguna de la Mica
A38: 037 | B38: ACTIVO | C38: =CONCATENATE(VLOOKUP($D38,CODIFICACIÓN_RUTA!$B$2:$C$3,2,0),MID($F38,1,1)&MID($F38,6,1),VLOOKUP($E38,CODIFICACIÓN_RUTA!$E$2:$F$10,2,0),$A38) -> 02E 07037 | D38: RURAL | E38: Valle de los Chillos | F38: ENTRE LAGUNAS Y PÁRAMOS | G38: RUTAS CONSOLIDADAS | H38: En esta aventura podremos disfrutar de del Volcán Antisana y sus paisajes que lo rodean, visitaremos uno de los miradores naturales que permiten observar el vuelo de los imponentes cóndores, además de de realizar un recorrido por el sendero Pato Urco a 4100 m.s.n.m | I38: Natural | J38: 7 | K38: 50 KM | L38: 3460 | M38: ALTA | N38: https://www.google.com/maps/d/u/0/edit?mid=1pOLRarYCsoE7QLFo-HYTJbTe9PYrwMM&usp=sharing | O38: Volcán Antisana | P38: Peñon del Isco | Q38: Laguna de Secas | R38: Laguna de la Mica
A39: 038 | B39: ACTIVO | C39: =CONCATENATE(VLOOKUP($D39,CODIFICACIÓN_RUTA!$B$2:$C$3,2,0),MID($F39,1,1)&MID($F39,6,1),VLOOKUP($E39,CODIFICACIÓN_RUTA!$E$2:$F$10,2,0),$A39) -> 01RC01038 | D39: URBANO | E39: Centro Histórico | F39: RUTA CONVENTO DE SANTO DOMINGO: CRIPTAS, LEYENDAS Y MISTERIO | G39: RUTAS CON POTENCIAL | H39: Se visitará el Refectorio del Convento, el Museo con una muestra de arte religioso, la capilla del Rosario, la iglesia y las catacumbas. Esto acompañados de personajes teatralizados que nos contarán historias y leyendas de esta convento. | I39: Cultural | J39: 1 | K39: 0.5 KM | L39: 2850 | M39: BAJA | N39: https://www.google.com/maps/d/u/0/edit?mid=1vWjsRCzlkrZE3GVnV5RzkejmqO0RX14&usp=sharing | O39: Museo de Santo Domingo Fray Pedro Bedón
A40: 039 | B40: ACTIVO | C40: =CONCATENATE(VLOOKUP($D40,CODIFICACIÓN_RUTA!$B$2:$C$3,2,0),MID($F40,1,1)&MID($F40,6,1),VLOOKUP($E40,CODIFICACIÓN_RUTA!$E$2:$F$10,2,0),$A40) -> 01RL01039 | D40: URBANO | E40: Centro Histórico | F40: RUTA LEGADO DE LOS FRANCISCANOS | G40: RUTAS CON POTENCIAL | H40: Conoceremos los dos complejos franciscanos que habitan en el Centro Histórico con gran influencia de arte quiteño, historia y vida religiosa. | I40: Cultural | J40: 4 | K40: 0.2 KM | L40: 2850 | M40: BAJA | N40: https://www.google.com/maps/d/u/0/edit?mid=1XxBokk1yWaWhGsSbfoSqf_romOBQaD8&usp=sharing | O40: Museo Fray Pedro Gocial San Francisco | P40: Iglesia de Santa Clara
...

Sheet Hoja1
C1: # | D1: TICKET | E1: ASUNTO | F1: ESTADO | G1: FECHA CIERRE | H1: FECHA APERTURA | I1: PRIORIDAD | J1: SOLICITANTE | K1: TÉCNICO ASIGNADO | L1: CATEGORÍA | M1: OBSERVACIÓN
C2: =ROW()-1 -> 1 | D2: 2 055 | E2: error sistema de facturación | F2: Cerrado | G2: 46140.384 | H2: 46140.378 | I2: Media | J2: Guamán Lizano Cristina Alejandra | K2: Chiluisa Armas Luis Patricio | L2: Soporte de aplicaciones de negocio > ERP Olympo
C3: =ROW()-1 -> 2 | D3: 2 054 | E3: SIN NÚMERO DE PREDIO | F3: En curso (asignado) | G3: 46140.361 | H3: 46140.349 | I3: Media | J3: Simbaña Chancusig Cristina de los Angeles | K3: Medina Iturre Edgar Fabricio | L3: Soporte de aplicaciones de negocio > SICET
C4: =ROW()-1 -> 3 | D4: 2 053 | E4: Acceso al NAS del Financiero | F4: Nuevo | G4: 46139.714 | H4: 46139.714 | I4: Media | J4: Solórzano Bomboza María Fernanda | K4: Medina Iturre Edgar Fabricio | L4: Servicios de Infraestructura y Seguridad > Gestión de Identidad y Acceso
C5: =ROW()-1 -> 4 | D5: 2 052 | E5: NÚMERO DE PREDIO VACIO | F5: En curso (asignado) | G5: 46139.688 | H5: 46139.661 | I5: Media | J5: Martínez Arias Adriana Elizabeth | K5: Medina Iturre Edgar Fabricio | L5: Soporte de aplicaciones de negocio > SICET
C6: =ROW()-1 -> 5 | D6: 2 051 | E6: SOLICITUD DE SOPORTE | F6: Cerrado | G6: 46139.647 | H6: 46139.598 | I6: Media | J6: Rea Sopalo Washington Manuel | K6: Chiluisa Armas Luis Patricio | L6: Soporte de aplicaciones de negocio > ERP Olympo
C7: =ROW()-1 -> 6 | D7: 2 050 | E7: Solicitud de apertura de tickets: Socialización de procesos de actualización y pasos a producción – ERP Olympo | F7: Resuelto | G7: 46139.467 | H7: 46139.449 | I7: Media | J7: Pacha Andrango Carlos Javier | K7: Chiluisa Armas Luis Patricio | L7: Soporte de aplicaciones de negocio > ERP Olympo
C8: =ROW()-1 -> 7 | D8: 2 049 | E8: NÚMERO DE PREDIO VACIO | F8: En curso (asignado) | G8: 46139.451 | H8: 46139.421 | I8: Media | J8: Martínez Arias Adriana Elizabeth | K8: Medina Iturre Edgar Fabricio | L8: Soporte de aplicaciones de negocio > SICET
C9: =ROW()-1 -> 8 | D9: 2 047 | E9: RV: Receptor correo administrativo | F9: Cerrado | G9: 46139.401 | H9: 46139.358 | I9: Media | J9: Pacha Andrango Carlos Javier | K9: Chiluisa Armas Luis Patricio | L9: Gestión de Software de Ofimática y Colaboración > Correo Electrónico Institucional
C10: =ROW()-1 -> 9 | D10: 2 048 | E10: RV: Solicitud de cambio de equipo electrónico – Coordinación de Gerencia | F10: En curso (asignado) | G10: 46139.374 | H10: 46139.37 | I10: Media | J10: Pacha Andrango Carlos Javier | K10: Chiluisa Armas Luis Patricio | L10: Soporte a Equipos de Cómputo y Periféricos > Computadora o laptop
C11: =ROW()-1 -> 10 | D11: 2 043 | E11: INSISTENCIA: [GLPI #0002038] ✔ Solicitud registrada | F11: Cerrado | G11: 46139.356 | H11: 46136.498 | I11: Media | J11: Ponce Solórzano Verónica Yolanda | K11: glpi | L11: Soporte de aplicaciones de negocio > ERP Olympo
C12: =ROW()-1 -> 11 | D12: 2 046 | E12: Pantallas Tiendas Quito | F12: En curso (asignado) | G12: 46139.356 | H12: 46136.67 | I12: Media | J12: Sánchez Uquillas Gabriel Sebastián | K12: Medina Iturre Edgar Fabricio | L12: Soporte a Equipos de Cómputo y Periféricos > Pantallas digitales
C13: =ROW()-1 -> 12 | D13: 2 011 | E13: RV: Vinculación de personal 21 de abril de 2026 | F13: Cerrado | G13: 46139.356 | H13: 46133.39 | I13: Media | J13: Pacha Andrango Carlos Javier | K13: Chiluisa Armas Luis Patricio | L13: Servicios de Infraestructura y Seguridad > Gestión de Identidad y Acceso
C14: =ROW()-1 -> 13 | D14: 2 045 | E14: CAMBIO DE PREDIO | F14: Cerrado | G14: 46138.666 | H14: 46136.645 | I14: Media | J14: Martínez Arias Adriana Elizabeth
C15: =ROW()-1 -> 14 | D15: 2 044 | E15: CAMBIO DE CORREO ELECTRONICO | F15: Cerrado | G15: 46138.666 | H15: 46136.599 | I15: Media | J15: Martínez Arias Adriana Elizabeth | K15: Medina Iturre Edgar Fabricio | L15: Soporte de aplicaciones de negocio > SICET
C16: =ROW()-1 -> 15 | D16: 2 038 | E16: SEGUIMIENTO: ESTADO DE CUENTA CONSEJO NACIONAL ELECTORAL DELEGACION PROVINCIAL DE PICHINCHA : REPORTE INCIDENCIA | F16: Cerrado | G16: 46136.498 | H16: 46135.403 | I16: Media | J16: Ponce Solórzano Verónica Yolanda
C17: =ROW()-1 -> 16 | D17: 2 014 | E17: RV: ACTUALIZACIÓN DE PREDIO | F17: Cerrado | G17: 46136.375 | H17: 46133.456 | I17: Media | J17: Pacha Andrango Carlos Javier | K17: Medina Iturre Edgar Fabricio | L17: Soporte de aplicaciones de negocio > SICET
C18: =ROW()-1 -> 17 | D18: 2 021 | E18: CAMBIO DE CORREO ELECTRÓNICO | F18: Cerrado | G18: 46136.375 | H18: 46133.537 | I18: Media | J18: Simbaña Chancusig Cristina de los Angeles | K18: Medina Iturre Edgar Fabricio | L18: Soporte de aplicaciones de negocio > SICET
C19: =ROW()-1 -> 18 | D19: 2 024 | E19: NÚMERO DE PREDIO VACIO | F19: Cerrado | G19: 46136.375 | H19: 46133.589 | I19: Media | J19: Simbaña Chancusig Cristina de los Angeles | K19: Medina Iturre Edgar Fabricio | L19: Soporte de aplicaciones de negocio > SICET
C20: =ROW()-1 -> 19 | D20: 2 025 | E20: ACTUALIZACION DE CORREO ELECTONICO | F20: Cerrado | G20: 46136.374 | H20: 46133.636 | I20: Media | J20: Bonilla Benavides Ana Cristina | K20: Medina Iturre Edgar Fabricio | L20: Soporte de aplicaciones de negocio > SICET
C21: =ROW()-1 -> 20 | D21: 2 026 | E21: ACCESO CARPETA DIRECTORIO | F21: Cerrado | G21: 46136.374 | H21: 46133.675 | I21: Media | J21: Rosero Marcillo María José | K21: Medina Iturre Edgar Fabricio | L21: Servicios de Infraestructura y Seguridad > Gestión de Identidad y Acceso
C22: =ROW()-1 -> 21 | D22: 2 028 | E22: DUPLICACIÓN DE REGISTRO TURÍSTICO | F22: Cerrado | G22: 46136.374 | H22: 46133.691 | I22: Media | J22: Simbaña Chancusig Cristina de los Angeles | K22: Medina Iturre Edgar Fabricio | L22: Soporte de aplicaciones de negocio > SICET
C23: =ROW()-1 -> 22 | D23: 2 027 | E23: RE: ACCESO CARPETA DIRECTORIO | F23: Cerrado | G23: 46136.374 | H23: 46133.68 | I23: Media | J23: Bucheli García Franklin Gustabo | K23: Medina Iturre Edgar Fabricio | L23: Servicios de Infraestructura y Seguridad > Gestión de Identidad y Acceso
C24: =ROW()-1 -> 23 | D24: 2 029 | E24: RV: DUPLICACIÓN DE REGISTRO TURÍSTICO | F24: Cerrado | G24: 46136.374 | H24: 46133.692 | I24: Media | J24: Simbaña Chancusig Cristina de los Angeles | K24: Medina Iturre Edgar Fabricio | L24: Soporte de aplicaciones de negocio > SICET
C25: =ROW()-1 -> 24 | D25: 2 030 | E25: CAMBIO DE CORREO ELECTRÓNICO | F25: Cerrado | G25: 46136.374 | H25: 46134.474 | I25: Media | J25: Simbaña Chancusig Cristina de los Angeles | K25: Medina Iturre Edgar Fabricio | L25: Soporte de aplicaciones de negocio > SICET
C26: =ROW()-1 -> 25 | D26: 2 033 | E26: ACTUALIZACIÓN DE LUAE CODIGO CIUU | F26: Cerrado | G26: 46136.373 | H26: 46134.551 | I26: Media | J26: Simbaña Chancusig Cristina de los Angeles | K26: Medina Iturre Edgar Fabricio | L26: Soporte de aplicaciones de negocio > SICET
C27: =ROW()-1 -> 26 | D27: 2 035 | E27: RV: REGISTRO TURÍSTICO EUROVIAJES ( RUC 1791226054001) | F27: Cerrado | G27: 46136.373 | H27: 46134.649 | I27: Media | J27: Simbaña Chancusig Cristina de los Angeles | K27: Medina Iturre Edgar Fabricio | L27: Soporte de aplicaciones de negocio > SICET
C28: =ROW()-1 -> 27 | D28: 2 036 | E28: RV: REGISTRO TURÍSTICO EUROVIAJES ( RUC 1791226054001) | F28: Cerrado | G28: 46136.373 | H28: 46134.649 | I28: Media | J28: Simbaña Chancusig Cristina de los Angeles | K28: Medina Iturre Edgar Fabricio | L28: Soporte de aplicaciones de negocio > SICET
... C41: =ROW()-1 -> 40 | D41: 2 023 | E41: Solicitud de modificación de estado de reforma presupuestaria | F41: Cerrado | G41: 46133.603 | H41: 46133.586 | I41: Media | J41: López Vásquez Jheisy Germania | K41: Chiluisa Armas Luis Patricio | L41: Soporte de aplicaciones de negocio > ERP Olympo
C42: =ROW()-1 -> 41 | D42: 2 022 | E42: Solicitud de modificación de estado de reforma presupuestaria | F42: Cerrado | G42: 46133.594 | H42: 46133.576 | I42: Media | J42: López Vásquez Jheisy Germania | K42: Chiluisa Armas Luis Patricio
C43: =ROW()-1 -> 42 | D43: 2 015 | E43: SOPORTE TECNICO NOTAS DE CREDITO: REPORTE INCIDENCIA (14-04-2024) | F43: Cerrado | G43: 46133.593 | H43: 46133.478 | I43: Media | J43: Ponce Solórzano Verónica Yolanda | K43: Chiluisa Armas Luis Patricio | L43: Soporte de aplicaciones de negocio > ERP Olympo
C44: =ROW()-1 -> 43 | D44: 2 020 | E44: SOPORTE TECNICO NOTAS DE CREDITO: REPORTE INCIDENCIA (14-04-2024) | F44: Cerrado | G44: 46133.592 | H44: 46133.515 | I44: Media | J44: Ponce Solórzano Verónica Yolanda
C45: =ROW()-1 -> 44 | D45: 2 013 | E45: RV: Proceso Reforma | F45: Cerrado | G45: 46133.461 | H45: 46133.456 | I45: Media | J45: Pacha Andrango Carlos Javier
C46: =ROW()-1 -> 45 | D46: 2 008 | E46: CAMBIO DE CORREO ELECTRÓNICO | F46: Cerrado | G46: 46133.459 | H46: 46132.597 | I46: Alta | J46: Simbaña Chancusig Cristina de los Angeles | K46: Medina Iturre Edgar Fabricio | L46: Soporte de aplicaciones de negocio > SICET
C47: =ROW()-1 -> 46 | D47: 2 010 | E47: Fw: Proceso reforma | F47: Cerrado | G47: 46133.459 | H47: 46132.948 | I47: Media | J47: Pacha Andrango Carlos Javier | K47: Medina Iturre Edgar Fabricio | L47: Soporte de aplicaciones de negocio > Sitra
C48: =ROW()-1 -> 47 | D48: 2 009 | E48: CAMBIO DE CORREO ELECTRÓNICO | F48: Cerrado | G48: 46133.456 | H48: 46132.683 | I48: Media | J48: Simbaña Chancusig Cristina de los Angeles | K48: Medina Iturre Edgar Fabricio | L48: Soporte de aplicaciones de negocio > SICET
C49: =ROW()-1 -> 48 | D49: 2 003 | E49: Publicación Barómetro | F49: Cerrado | G49: 46133.456 | H49: 46132.359 | I49: Media | J49: Utreras Fuentes Ruth Elena | K49: Medina Iturre Edgar Fabricio | L49: Soporte de aplicaciones de negocio > Portal Institución
C50: =ROW()-1 -> 49 | D50: 1 985 | E50: Solicitud de implementación de numeración en la Gaceta Tributaria Digital de la EPMGDTR | F50: Cerrado | G50: 46133.456 | H50: 46128.512 | I50: Media | J50: Tipán Gavilanes Daysi Lizbeth | K50: Medina Iturre Edgar Fabricio | L50: Soporte de aplicaciones de negocio > Portal Institución
C51: =ROW()-1 -> 50 | D51: 2 001 | E51: CAMBIO DE CORREO ELECTRÓNICO | F51: Cerrado | G51: 46133.455 | H51: 46129.63 | I51: Media | J51: Simbaña Chancusig Cristina de los Angeles | K51: Medina Iturre Edgar Fabricio | L51: Soporte de aplicaciones de negocio > SICET
C52: =ROW()-1 -> 51 | D52: 1 969 | E52: Infocus | F52: Cerrado | G52: 46133.455 | H52: 46128.476 | I52: Media | J52: Plaza Chicaiza Karla Gabriela | K52: Medina Iturre Edgar Fabricio | L52: Soporte a Equipos de Cómputo y Periféricos > Proyectores
...

Sheet Resumen
B1: 📊 RESUMEN DE TICKETS DE SOPORTE TÉCNICO
B3: INDICADORES CLAVE (KPIs)
B5: Total Tickets | C5: Cerrados | D5: Resueltos | E5: En Curso | F5: Nuevos | G5: Prioridad Alta
B6: =COUNTA(TablaTickets[TICKET]) -> 155 | C6: =COUNTIF(TablaTickets[ESTADO],"*Cerrado*") -> 145 | D6: =COUNTIF(TablaTickets[ESTADO],"*Resuelto*") -> 1 | E6: =COUNTIF(TablaTickets[ESTADO],"*En curso*") -> 8 | F6: =COUNTIF(TablaTickets[ESTADO],"*Nuevo*") -> 1 | G6: =COUNTIF(TablaTickets[PRIORIDAD],"*Alta*") -> 30
B9: 1. Tickets por ESTADO | E9: 2. Tickets por PRIORIDAD
B10: Estado | C10: Cantidad | E10: Prioridad | F10: Cantidad
B11: {=_xlfn._xlws.SORT(_xlfn.UNIQUE(TablaTickets[ESTADO]))} -> Cerrado | C11: {=COUNTIF(TablaTickets[ESTADO],_xlfn.ANCHORARRAY(B11))} -> 145 | E11: {=_xlfn._xlws.SORT(_xlfn.UNIQUE(TablaTickets[PRIORIDAD]))} -> Alta | F11: {=COUNTIF(TablaTickets[PRIORIDAD],_xlfn.ANCHORARRAY(E11))} -> 30
B12: En curso (asignado) | C12: 8 | E12: Baja | F12: 1
B13: Nuevo | C13: 1 | E13: Media | F13: 124
B14: Resuelto | C14: 1
B20: 3. Tickets por TÉCNICO ASIGNADO | E20: 4. Top 10 CATEGORÍAS
B21: Técnico | C21: Cantidad | E21: Categoría | F21: Cantidad
B22: {=_xlfn._xlws.SORT(_xlfn.UNIQUE(_xlfn._xlws.FILTER(TablaTickets[TÉCNICO ASIGNADO],TablaTickets[TÉCNICO ASIGNADO]<>"")))} -> Casa Chanaluisa Alex Wladimir | C22: {=COUNTIF(TablaTickets[TÉCNICO ASIGNADO],_xlfn.ANCHORARRAY(B22))} -> 1 | E22: {=_xlfn.LET(_xlpm.u,_xlfn.UNIQUE(_xlfn._xlws.FILTER(TablaTickets[CATEGORÍA],TablaTickets[CATEGORÍA]<>"")),_xlpm.c,COUNTIF(TablaTickets[CATEGORÍA],_xlpm.u),_xlpm.s,_xlfn.SORTBY(_xlpm.u,_xlpm.c,-1),_xlfn.TAKE(_xlpm.s,10))} -> Soporte de aplicaciones de negocio > SICET | F22: {=COUNTIF(TablaTickets[CATEGORÍA],_xlfn.ANCHORARRAY(E22))} -> 44
B23: Chiluisa Armas Luis Patricio | C23: 67 | E23: Soporte de aplicaciones de negocio > ERP Olympo | F23: 31
B24: glpi | C24: 1 | E24: Servicios de Infraestructura y Seguridad > Gestión de Identidad y Acceso | F24: 15
B25: glpi | C25: 2 | E25: Soporte de aplicaciones de negocio > Sitra | F25: 9
B26: Medina Iturre Edgar Fabricio | C26: 71 | E26: Soporte de aplicaciones de negocio > Portal Institución | F26: 8
E27: Soporte a Equipos de Cómputo y Periféricos > Computadora o laptop | F27: 7
E28: Soporte a Equipos de Cómputo y Periféricos > Pantallas digitales | F28: 4
E29: Soporte a Equipos de Cómputo y Periféricos > Impresora | F29: 3
E30: Servicios de Infraestructura y Seguridad > Copias de Seguridad y Recuperación de Información | F30: 3
E31: Gestión de Software de Ofimática y Colaboración > Correo Electrónico Institucional | F31: 2

Sheet MANZANA_RUTA_DPA
B1: DPA_MANZANA
A2: 01RD01001 | B2: 170150215005003
A3: 01RD01001 | B3: 170150214009002
A4: 01RD01001 | B4: 170150214009001 | D4: La codificación DPA por manzana se identifica en la totalidad de manzanas que suponen parte lineal de la ruta en mención
A5: 01RD01001 | B5: 170150214010001
A6: 01RD01001 | B6: 170150236008002
A7: 01RD01001 | B7: 170150215004001
A8: 01RD01001 | B8: 170150214008001
A9: 01RD01001 | B9: 170150215009004
A10: 01RD01001 | B10: 170150215008004
A11: 01RD01001 | B11: 170150215008003
A12: 01RD01001 | B12: 170150215008006
A13: 01RD01001 | B13: 170150215008005
A14: 01RD01001 | B14: 170150215008007
A15: 01RD01001 | B15: 170150215007003
A16: 01RD01001 | B16: 170150215007002
... A1927: 02RE05014 | B1927: 170150010008011
